Workbook

Sheet 2011
C1: NBP | F1: NBP - 38 | I1: PB1 | L1: PB1-38 | O1: PB2 | R1: PB2-38 | U1: PB3 | X1: PB4 | AA1: PB5 | AD1: PB6
A2: Date | B2: JDAY | C2: AveFol | D2: AveWatt | E2: AveHazel | F2: AveFol | G2: AveWatt | H2: AveHazel | I2: AveFol | J2: AveWatt | K2: AveHazel | L2: AveFol | M2: AveWatt | N2: AveHazel | O2: AveFol | P2: AveWatt | Q2: AveHazel | R2: AveFol | S2: AveWatt | T2: AveHazel | U2: AveFol | V2: AveWatt | W2: AveHazel | X2: AveFol | Y2: AveWatt | Z2: AveHazel | AA2: AveFol | AB2: AveWatt | AC2: AveHazel | AD2: AveFol | AE2: AveWatt | AF2: AveHazel
A3: 46280 | B3: 258 | C3: 18.11 | E3: 18.32 | F3: 18.11 | H3: 18.32 | I3: 18.11 | K3: 18.32 | L3: 18.11 | N3: 18.32 | O3: 18.11 | Q3: 18.32 | R3: 18.11 | T3: 18.32 | U3: 18.11 | W3: 18.32 | X3: 18.11 | Z3: 18.32 | AA3: 18.11 | AC3: 18.32 | AD3: 18.11 | AF3: 18.32
A4: 46281 | B4: 259 | C4: 19.26 | E4: 19.02 | F4: 19.26 | H4: 19.02 | I4: 19.26 | K4: 19.02 | L4: 19.26 | N4: 19.02 | O4: 19.26 | Q4: 19.02 | R4: 19.26 | T4: 19.02 | U4: 19.26 | W4: 19.02 | X4: 19.26 | Z4: 19.02 | AA4: 19.26 | AC4: 19.02 | AD4: 19.26 | AF4: 19.02
A5: 46282 | B5: 260 | C5: 17.84 | E5: 18.07 | F5: 17.84 | H5: 18.07 | I5: 17.84 | K5: 18.07 | L5: 17.84 | N5: 18.07 | O5: 17.84 | Q5: 18.07 | R5: 17.84 | T5: 18.07 | U5: 17.84 | W5: 18.07 | X5: 17.84 | Z5: 18.07 | AA5: 17.84 | AC5: 18.07 | AD5: 17.84 | AF5: 18.07
A6: 46283 | B6: 261 | C6: 17.61 | D6: 19.7 | E6: 18.14 | F6: 17.61 | G6: 19.7 | H6: 18.14 | I6: 17.61 | J6: 19.7 | K6: 18.14 | L6: 17.61 | M6: 19.7 | N6: 18.14 | O6: 17.61 | P6: 19.7 | Q6: 18.14 | R6: 17.61 | S6: 19.7 | T6: 18.14 | U6: 17.61 | V6: 19.7 | W6: 18.14 | X6: 17.61 | Y6: 19.7 | Z6: 18.14 | AA6: 17.61 | AB6: 19.7 | AC6: 18.14 | AD6: 17.61 | AE6: 19.7 | AF6: 18.14
A7: 46284 | B7: 262 | C7: 17.78 | D7: 20.58 | E7: 18.38 | F7: 17.78 | G7: 20.58 | H7: 18.38 | I7: 17.78 | J7: 20.58 | K7: 18.38 | L7: 17.78 | M7: 20.58 | N7: 18.38 | O7: 17.78 | P7: 20.58 | Q7: 18.38 | R7: 17.78 | S7: 20.58 | T7: 18.38 | U7: 17.78 | V7: 20.58 | W7: 18.38 | X7: 17.78 | Y7: 20.58 | Z7: 18.38 | AA7: 17.78 | AB7: 20.58 | AC7: 18.38 | AD7: 17.78 | AE7: 20.58 | AF7: 18.38
A8: 46285 | B8: 263 | C8: 17.36 | D8: 20.05 | E8: 18.15 | F8: 17.36 | G8: 20.05 | H8: 18.15 | I8: 17.36 | J8: 20.05 | K8: 18.15 | L8: 17.36 | M8: 20.05 | N8: 18.15 | O8: 17.36 | P8: 20.05 | Q8: 18.15 | R8: 17.36 | S8: 20.05 | T8: 18.15 | U8: 17.36 | V8: 20.05 | W8: 18.15 | X8: 17.36 | Y8: 20.05 | Z8: 18.15 | AA8: 17.36 | AB8: 20.05 | AC8: 18.15 | AD8: 17.36 | AE8: 20.05 | AF8: 18.15
A9: 46286 | B9: 264 | C9: 17.95 | D9: 20.02 | E9: 18.57 | F9: 17.95 | G9: 20.02 | H9: 18.57 | I9: 17.95 | J9: 20.02 | K9: 18.57 | L9: 17.95 | M9: 20.02 | N9: 18.57 | O9: 17.95 | P9: 20.02 | Q9: 18.57 | R9: 17.95 | S9: 20.02 | T9: 18.57 | U9: 17.95 | V9: 20.02 | W9: 18.57 | X9: 17.95 | Y9: 20.02 | Z9: 18.57 | AA9: 17.95 | AB9: 20.02 | AC9: 18.57 | AD9: 17.95 | AE9: 20.02 | AF9: 18.57
A10: 46287 | B10: 265 | C10: 18.06 | D10: 20 | E10: 18.59 | F10: 18.06 | G10: 20 | H10: 18.59 | I10: 18.06 | J10: 20 | K10: 18.59 | L10: 18.06 | M10: 20 | N10: 18.59 | O10: 18.06 | P10: 20 | Q10: 18.59 | R10: 18.06 | S10: 20 | T10: 18.59 | U10: 18.06 | V10: 20 | W10: 18.59 | X10: 18.06 | Y10: 20 | Z10: 18.59 | AA10: 18.06 | AB10: 20 | AC10: 18.59 | AD10: 18.06 | AE10: 20 | AF10: 18.59
A11: 46288 | B11: 266 | C11: 18.12 | D11: 20.01 | E11: 18.7 | F11: 18.12 | G11: 20.01 | H11: 18.7 | I11: 18.12 | J11: 20.01 | K11: 18.7 | L11: 18.12 | M11: 20.01 | N11: 18.7 | O11: 18.12 | P11: 20.01 | Q11: 18.7 | R11: 18.12 | S11: 20.01 | T11: 18.7 | U11: 18.12 | V11: 20.01 | W11: 18.7 | X11: 18.12 | Y11: 20.01 | Z11: 18.7 | AA11: 18.12 | AB11: 20.01 | AC11: 18.7 | AD11: 18.12 | AE11: 20.01 | AF11: 18.7
A12: 46289 | B12: 267 | C12: 18.06 | D12: 19.56 | E12: 18.36 | F12: 18.06 | G12: 19.56 | H12: 18.36 | I12: 18.06 | J12: 19.56 | K12: 18.36 | L12: 18.06 | M12: 19.56 | N12: 18.36 | O12: 18.06 | P12: 19.56 | Q12: 18.36 | R12: 18.06 | S12: 19.56 | T12: 18.36 | U12: 18.06 | V12: 19.56 | W12: 18.36 | X12: 18.06 | Y12: 19.56 | Z12: 18.36 | AA12: 18.06 | AB12: 19.56 | AC12: 18.36 | AD12: 18.06 | AE12: 19.56 | AF12: 18.36
A13: 46290 | B13: 268 | C13: 17.78 | D13: 18.75 | E13: 17.82 | F13: 17.78 | G13: 18.75 | H13: 17.82 | I13: 17.78 | J13: 18.75 | K13: 17.82 | L13: 17.78 | M13: 18.75 | N13: 17.82 | O13: 17.78 | P13: 18.75 | Q13: 17.82 | R13: 17.78 | S13: 18.75 | T13: 17.82 | U13: 17.78 | V13: 18.75 | W13: 17.82 | X13: 17.78 | Y13: 18.75 | Z13: 17.82 | AA13: 17.78 | AB13: 18.75 | AC13: 17.82 | AD13: 17.78 | AE13: 18.75 | AF13: 17.82
A14: 46291 | B14: 269 | C14: 18.05 | D14: 18.99 | E14: 18.07 | F14: 18.05 | G14: 18.99 | H14: 18.07 | I14: 18.05 | J14: 18.99 | K14: 18.07 | L14: 18.05 | M14: 18.99 | N14: 18.07 | O14: 18.05 | P14: 18.99 | Q14: 18.07 | R14: 18.05 | S14: 18.99 | T14: 18.07 | U14: 18.05 | V14: 18.99 | W14: 18.07 | X14: 18.05 | Y14: 18.99 | Z14: 18.07 | AA14: 18.05 | AB14: 18.99 | AC14: 18.07 | AD14: 18.05 | AE14: 18.99 | AF14: 18.07
A15: 46292 | B15: 270 | C15: 18.37 | D15: 19.36 | E15: 18.43 | F15: 18.37 | G15: 19.36 | H15: 18.43 | I15: 18.37 | J15: 19.36 | K15: 18.43 | L15: 18.37 | M15: 19.36 | N15: 18.43 | O15: 18.37 | P15: 19.36 | Q15: 18.43 | R15: 18.37 | S15: 19.36 | T15: 18.43 | U15: 18.37 | V15: 19.36 | W15: 18.43 | X15: 18.37 | Y15: 19.36 | Z15: 18.43 | AA15: 18.37 | AB15: 19.36 | AC15: 18.43 | AD15: 18.37 | AE15: 19.36 | AF15: 18.43
A16: 46293 | B16: 271 | C16: 18.45 | D16: 19.81 | E16: 18.69 | F16: 17.83 | G16: 19.81 | H16: 18.29 | I16: 18.45 | J16: 19.81 | K16: 18.69 | L16: 17.83 | M16: 19.81 | N16: 18.29 | O16: 18.45 | P16: 19.81 | Q16: 18.69 | R16: 17.83 | S16: 19.81 | T16: 18.29 | U16: 18.45 | V16: 19.81 | W16: 18.69 | X16: 18.45 | Y16: 19.81 | Z16: 18.69 | AA16: 18.21 | AB16: 19.81 | AC16: 18.53 | AD16: 18.45 | AE16: 19.81 | AF16: 18.69
A17: 46294 | B17: 272 | C17: 18.46 | D17: 20.1 | E17: 18.74 | F17: 17.05 | G17: 20.1 | H17: 17.81 | I17: 18.46 | J17: 20.1 | K17: 18.74 | L17: 17.05 | M17: 20.1 | N17: 17.81 | O17: 18.46 | P17: 20.1 | Q17: 18.74 | R17: 17.05 | S17: 20.1 | T17: 17.81 | U17: 18.46 | V17: 20.1 | W17: 18.74 | X17: 18.46 | Y17: 20.1 | Z17: 18.74 | AA17: 18 | AB17: 20.1 | AC17: 18.44 | AD17: 18.46 | AE17: 20.1 | AF17: 18.74
... A79: 46356 | B79: 334 | C79: 12.62 | D79: 12.24 | E79: 13.34 | F79: 12.66 | G79: 12.28 | H79: 13.37 | I79: 12.94 | J79: 12.69 | K79: 13.55 | L79: 12.99 | M79: 12.74 | N79: 13.59 | O79: 12.92 | P79: 12.71 | Q79: 13.54 | R79: 12.96 | S79: 12.78 | T79: 13.57 | U79: 12.66 | V79: 12.45 | W79: 13.36 | X79: 12.97 | Y79: 12.67 | Z79: 13.58 | AA79: 12.82 | AB79: 12.53 | AC79: 13.47 | AD79: 12.93 | AE79: 12.63 | AF79: 13.55

Sheet 2011 °F
C1: NBP | F1: NBP - 38 | I1: PB1 | L1: PB1-38 | O1: PB2 | R1: PB2-38 | U1: PB3 | X1: PB4 | AA1: PB5 | AD1: PB6
A2: Date | B2: JDAY | C2: AveFol | D2: AveWatt | E2: AveHazel | F2: AveFol | G2: AveWatt | H2: AveHazel | I2: AveFol | J2: AveWatt | K2: AveHazel | L2: AveFol | M2: AveWatt | N2: AveHazel | O2: AveFol | P2: AveWatt | Q2: AveHazel | R2: AveFol | S2: AveWatt | T2: AveHazel | U2: AveFol | V2: AveWatt | W2: AveHazel | X2: AveFol | Y2: AveWatt | Z2: AveHazel | AA2: AveFol | AB2: AveWatt | AC2: AveHazel | AD2: AveFol | AE2: AveWatt | AF2: AveHazel
A3: 46280 | B3: 258 | C3: ='2011'!C3*9/5+32 -> 64.598 | E3: ='2011'!E3*9/5+32 -> 64.976 | F3: ='2011'!F3*9/5+32 -> 64.598 | H3: ='2011'!H3*9/5+32 -> 64.976 | I3: ='2011'!I3*9/5+32 -> 64.598 | K3: ='2011'!K3*9/5+32 -> 64.976 | L3: ='2011'!L3*9/5+32 -> 64.598 | N3: ='2011'!N3*9/5+32 -> 64.976 | O3: ='2011'!O3*9/5+32 -> 64.598 | Q3: ='2011'!Q3*9/5+32 -> 64.976 | R3: ='2011'!R3*9/5+32 -> 64.598 | T3: ='2011'!T3*9/5+32 -> 64.976 | U3: ='2011'!U3*9/5+32 -> 64.598 | W3: ='2011'!W3*9/5+32 -> 64.976 | X3: ='2011'!X3*9/5+32 -> 64.598 | Z3: ='2011'!Z3*9/5+32 -> 64.976 | AA3: ='2011'!AA3*9/5+32 -> 64.598 | AC3: ='2011'!AC3*9/5+32 -> 64.976 | AD3: ='2011'!AD3*9/5+32 -> 64.598 | AF3: ='2011'!AF3*9/5+32 -> 64.976
A4: 46281 | B4: 259 | C4: ='2011'!C4*9/5+32 -> 66.668 | E4: ='2011'!E4*9/5+32 -> 66.236 | F4: ='2011'!F4*9/5+32 -> 66.668 | H4: ='2011'!H4*9/5+32 -> 66.236 | I4: ='2011'!I4*9/5+32 -> 66.668 | K4: ='2011'!K4*9/5+32 -> 66.236 | L4: ='2011'!L4*9/5+32 -> 66.668 | N4: ='2011'!N4*9/5+32 -> 66.236 | O4: ='2011'!O4*9/5+32 -> 66.668 | Q4: ='2011'!Q4*9/5+32 -> 66.236 | R4: ='2011'!R4*9/5+32 -> 66.668 | T4: ='2011'!T4*9/5+32 -> 66.236 | U4: ='2011'!U4*9/5+32 -> 66.668 | W4: ='2011'!W4*9/5+32 -> 66.236 | X4: ='2011'!X4*9/5+32 -> 66.668 | Z4: ='2011'!Z4*9/5+32 -> 66.236 | AA4: ='2011'!AA4*9/5+32 -> 66.668 | AC4: ='2011'!AC4*9/5+32 -> 66.236 | AD4: ='2011'!AD4*9/5+32 -> 66.668 | AF4: ='2011'!AF4*9/5+32 -> 66.236
A5: 46282 | B5: 260 | C5: ='2011'!C5*9/5+32 -> 64.112 | E5: ='2011'!E5*9/5+32 -> 64.526 | F5: ='2011'!F5*9/5+32 -> 64.112 | H5: ='2011'!H5*9/5+32 -> 64.526 | I5: ='2011'!I5*9/5+32 -> 64.112 | K5: ='2011'!K5*9/5+32 -> 64.526 | L5: ='2011'!L5*9/5+32 -> 64.112 | N5: ='2011'!N5*9/5+32 -> 64.526 | O5: ='2011'!O5*9/5+32 -> 64.112 | Q5: ='2011'!Q5*9/5+32 -> 64.526 | R5: ='2011'!R5*9/5+32 -> 64.112 | T5: ='2011'!T5*9/5+32 -> 64.526 | U5: ='2011'!U5*9/5+32 -> 64.112 | W5: ='2011'!W5*9/5+32 -> 64.526 | X5: ='2011'!X5*9/5+32 -> 64.112 | Z5: ='2011'!Z5*9/5+32 -> 64.526 | AA5: ='2011'!AA5*9/5+32 -> 64.112 | AC5: ='2011'!AC5*9/5+32 -> 64.526 | AD5: ='2011'!AD5*9/5+32 -> 64.112 | AF5: ='2011'!AF5*9/5+32 -> 64.526
A6: 46283 | B6: 261 | C6: ='2011'!C6*9/5+32 -> 63.698 | D6: ='2011'!D6*9/5+32 -> 67.46 | E6: ='2011'!E6*9/5+32 -> 64.652 | F6: ='2011'!F6*9/5+32 -> 63.698 | G6: ='2011'!G6*9/5+32 -> 67.46 | H6: ='2011'!H6*9/5+32 -> 64.652 | I6: ='2011'!I6*9/5+32 -> 63.698 | J6: ='2011'!J6*9/5+32 -> 67.46 | ... AF6: ='2011'!AF6*9/5+32 -> 64.652
A7: 46284 | B7: 262 | C7: ='2011'!C7*9/5+32 -> 64.004 | D7: ='2011'!D7*9/5+32 -> 69.044 | E7: ='2011'!E7*9/5+32 -> 65.084 | F7: ='2011'!F7*9/5+32 -> 64.004 | G7: ='2011'!G7*9/5+32 -> 69.044 | H7: ='2011'!H7*9/5+32 -> 65.084 | I7: ='2011'!I7*9/5+32 -> 64.004 | J7: ='2011'!J7*9/5+32 -> 69.044 | ... AF7: ='2011'!AF7*9/5+32 -> 65.084
A8: 46285 | B8: 263 | C8: ='2011'!C8*9/5+32 -> 63.248 | D8: ='2011'!D8*9/5+32 -> 68.09 | E8: ='2011'!E8*9/5+32 -> 64.67 | F8: ='2011'!F8*9/5+32 -> 63.248 | G8: ='2011'!G8*9/5+32 -> 68.09 | H8: ='2011'!H8*9/5+32 -> 64.67 | I8: ='2011'!I8*9/5+32 -> 63.248 | J8: ='2011'!J8*9/5+32 -> 68.09 | ... AF8: ='2011'!AF8*9/5+32 -> 64.67
A9: 46286 | B9: 264 | C9: ='2011'!C9*9/5+32 -> 64.31 | D9: ='2011'!D9*9/5+32 -> 68.036 | E9: ='2011'!E9*9/5+32 -> 65.426 | F9: ='2011'!F9*9/5+32 -> 64.31 | G9: ='2011'!G9*9/5+32 -> 68.036 | H9: ='2011'!H9*9/5+32 -> 65.426 | I9: ='2011'!I9*9/5+32 -> 64.31 | J9: ='2011'!J9*9/5+32 -> 68.036 | ... AF9: ='2011'!AF9*9/5+32 -> 65.426
A10: 46287 | B10: 265 | C10: ='2011'!C10*9/5+32 -> 64.508 | D10: ='2011'!D10*9/5+32 -> 68 | E10: ='2011'!E10*9/5+32 -> 65.462 | F10: ='2011'!F10*9/5+32 -> 64.508 | G10: ='2011'!G10*9/5+32 -> 68 | H10: ='2011'!H10*9/5+32 -> 65.462 | I10: ='2011'!I10*9/5+32 -> 64.508 | J10: ='2011'!J10*9/5+32 -> 68 | ... AF10: ='2011'!AF10*9/5+32 -> 65.462
A11: 46288 | B11: 266 | C11: ='2011'!C11*9/5+32 -> 64.616 | D11: ='2011'!D11*9/5+32 -> 68.018 | E11: ='2011'!E11*9/5+32 -> 65.66 | F11: ='2011'!F11*9/5+32 -> 64.616 | G11: ='2011'!G11*9/5+32 -> 68.018 | H11: ='2011'!H11*9/5+32 -> 65.66 | I11: ='2011'!I11*9/5+32 -> 64.616 | J11: ='2011'!J11*9/5+32 -> 68.018 | ... AF11: ='2011'!AF11*9/5+32 -> 65.66
A12: 46289 | B12: 267 | C12: ='2011'!C12*9/5+32 -> 64.508 | D12: ='2011'!D12*9/5+32 -> 67.208 | E12: ='2011'!E12*9/5+32 -> 65.048 | F12: ='2011'!F12*9/5+32 -> 64.508 | G12: ='2011'!G12*9/5+32 -> 67.208 | H12: ='2011'!H12*9/5+32 -> 65.048 | I12: ='2011'!I12*9/5+32 -> 64.508 | J12: ='2011'!J12*9/5+32 -> 67.208 | ... AF12: ='2011'!AF12*9/5+32 -> 65.048
A13: 46290 | B13: 268 | C13: ='2011'!C13*9/5+32 -> 64.004 | D13: ='2011'!D13*9/5+32 -> 65.75 | E13: ='2011'!E13*9/5+32 -> 64.076 | F13: ='2011'!F13*9/5+32 -> 64.004 | G13: ='2011'!G13*9/5+32 -> 65.75 | H13: ='2011'!H13*9/5+32 -> 64.076 | I13: ='2011'!I13*9/5+32 -> 64.004 | J13: ='2011'!J13*9/5+32 -> 65.75 | ... AF13: ='2011'!AF13*9/5+32 -> 64.076
A14: 46291 | B14: 269 | C14: ='2011'!C14*9/5+32 -> 64.49 | D14: ='2011'!D14*9/5+32 -> 66.182 | E14: ='2011'!E14*9/5+32 -> 64.526 | F14: ='2011'!F14*9/5+32 -> 64.49 | G14: ='2011'!G14*9/5+32 -> 66.182 | H14: ='2011'!H14*9/5+32 -> 64.526 | I14: ='2011'!I14*9/5+32 -> 64.49 | J14: ='2011'!J14*9/5+32 -> 66.182 | ... AF14: ='2011'!AF14*9/5+32 -> 64.526
A15: 46292 | B15: 270 | C15: ='2011'!C15*9/5+32 -> 65.066 | D15: ='2011'!D15*9/5+32 -> 66.848 | E15: ='2011'!E15*9/5+32 -> 65.174 | F15: ='2011'!F15*9/5+32 -> 65.066 | G15: ='2011'!G15*9/5+32 -> 66.848 | H15: ='2011'!H15*9/5+32 -> 65.174 | I15: ='2011'!I15*9/5+32 -> 65.066 | J15: ='2011'!J15*9/5+32 -> 66.848 | ... AF15: ='2011'!AF15*9/5+32 -> 65.174
A16: 46293 | B16: 271 | C16: ='2011'!C16*9/5+32 -> 65.21 | D16: ='2011'!D16*9/5+32 -> 67.658 | E16: ='2011'!E16*9/5+32 -> 65.642 | F16: ='2011'!F16*9/5+32 -> 64.094 | G16: ='2011'!G16*9/5+32 -> 67.658 | H16: ='2011'!H16*9/5+32 -> 64.922 | I16: ='2011'!I16*9/5+32 -> 65.21 | J16: ='2011'!J16*9/5+32 -> 67.658 | ... AF16: ='2011'!AF16*9/5+32 -> 65.642
A17: 46294 | B17: 272 | C17: ='2011'!C17*9/5+32 -> 65.228 | D17: ='2011'!D17*9/5+32 -> 68.18 | E17: ='2011'!E17*9/5+32 -> 65.732 | F17: ='2011'!F17*9/5+32 -> 62.69 | G17: ='2011'!G17*9/5+32 -> 68.18 | H17: ='2011'!H17*9/5+32 -> 64.058 | I17: ='2011'!I17*9/5+32 -> 65.228 | J17: ='2011'!J17*9/5+32 -> 68.18 | ... AF17: ='2011'!AF17*9/5+32 -> 65.732
... A79: 46356 | B79: 334 | C79: ='2011'!C79*9/5+32 -> 54.716 | D79: ='2011'!D79*9/5+32 -> 54.032 | E79: ='2011'!E79*9/5+32 -> 56.012 | F79: ='2011'!F79*9/5+32 -> 54.788 | G79: ='2011'!G79*9/5+32 -> 54.104 | H79: ='2011'!H79*9/5+32 -> 56.066 | I79: ='2011'!I79*9/5+32 -> 55.292 | J79: ='2011'!J79*9/5+32 -> 54.842 | ... AF79: ='2011'!AF79*9/5+32 -> 56.39

Sheet 2014
C1: NBP | F1: NBP - 38 | I1: PB1 | L1: PB1-38 | O1: PB2 | R1: PB2-38 | U1: PB3 | X1: PB4 | AA1: PB5 | AD1: PB6
A2: Date | B2: JDAY | C2: AveFol | D2: AveWatt | E2: AveHazel | F2: AveFol | G2: AveWatt | H2: AveHazel | I2: AveFol | J2: AveWatt | K2: AveHazel | L2: AveFol | M2: AveWatt | N2: AveHazel | O2: AveFol | P2: AveWatt | Q2: AveHazel | R2: AveFol | S2: AveWatt | T2: AveHazel | U2: AveFol | V2: AveWatt | W2: AveHazel | X2: AveFol | Y2: AveWatt | Z2: AveHazel | AA2: AveFol | AB2: AveWatt | AC2: AveHazel | AD2: AveFol | AE2: AveWatt | AF2: AveHazel
A3: 46280 | B3: 258 | C3: 18.1 | E3: 18.68 | F3: 18.1 | H3: 18.68 | I3: 18.1 | K3: 18.68 | L3: 18.1 | N3: 18.68 | O3: 18.1 | Q3: 18.68 | R3: 18.1 | T3: 18.68 | U3: 18.1 | W3: 18.68 | X3: 18.1 | Z3: 18.68 | AA3: 18.1 | AC3: 18.68 | AD3: 18.1 | AF3: 18.68
A4: 46281 | B4: 259 | C4: 19.96 | E4: 19.83 | F4: 19.96 | H4: 19.83 | I4: 19.96 | K4: 19.83 | L4: 19.96 | N4: 19.83 | O4: 19.96 | Q4: 19.83 | R4: 19.96 | T4: 19.83 | U4: 19.96 | W4: 19.83 | X4: 19.96 | Z4: 19.83 | AA4: 19.96 | AC4: 19.83 | AD4: 19.96 | AF4: 19.83
A5: 46282 | B5: 260 | C5: 18.45 | E5: 18.79 | F5: 18.45 | H5: 18.79 | I5: 18.45 | K5: 18.79 | L5: 18.45 | N5: 18.79 | O5: 18.45 | Q5: 18.79 | R5: 18.45 | T5: 18.79 | U5: 18.45 | W5: 18.79 | X5: 18.45 | Z5: 18.79 | AA5: 18.45 | AC5: 18.79 | AD5: 18.45 | AF5: 18.79
A6: 46283 | B6: 261 | C6: 19.78 | D6: 19.69 | E6: 19.62 | F6: 19.78 | G6: 19.69 | H6: 19.62 | I6: 19.78 | J6: 19.69 | K6: 19.62 | L6: 19.78 | M6: 19.69 | N6: 19.62 | O6: 19.78 | P6: 19.69 | Q6: 19.62 | R6: 19.78 | S6: 19.69 | T6: 19.62 | U6: 19.78 | V6: 19.69 | W6: 19.62 | X6: 19.78 | Y6: 19.69 | Z6: 19.62 | AA6: 19.78 | AB6: 19.69 | AC6: 19.62 | AD6: 19.78 | AE6: 19.69 | AF6: 19.62
A7: 46284 | B7: 262 | C7: 20.03 | D7: 20.43 | E7: 19.72 | F7: 20.03 | G7: 20.43 | H7: 19.72 | I7: 20.03 | J7: 20.43 | K7: 19.72 | L7: 20.03 | M7: 20.43 | N7: 19.72 | O7: 20.03 | P7: 20.43 | Q7: 19.72 | R7: 20.03 | S7: 20.43 | T7: 19.72 | U7: 20.03 | V7: 20.43 | W7: 19.72 | X7: 20.03 | Y7: 20.43 | Z7: 19.72 | AA7: 20.03 | AB7: 20.43 | AC7: 19.72 | AD7: 20.03 | AE7: 20.43 | AF7: 19.72
A8: 46285 | B8: 263 | C8: 18.72 | D8: 19.96 | E8: 18.92 | F8: 18.72 | G8: 19.96 | H8: 18.92 | I8: 18.72 | J8: 19.96 | K8: 18.92 | L8: 18.72 | M8: 19.96 | N8: 18.92 | O8: 18.72 | P8: 19.96 | Q8: 18.92 | R8: 18.72 | S8: 19.96 | T8: 18.92 | U8: 18.72 | V8: 19.96 | W8: 18.92 | X8: 18.72 | Y8: 19.96 | Z8: 18.92 | AA8: 18.72 | AB8: 19.96 | AC8: 18.92 | AD8: 18.72 | AE8: 19.96 | AF8: 18.92
A9: 46286 | B9: 264 | C9: 19.3 | D9: 20.1 | E9: 19.08 | F9: 19.3 | G9: 20.1 | H9: 19.08 | I9: 19.3 | J9: 20.1 | K9: 19.08 | L9: 19.3 | M9: 20.1 | N9: 19.08 | O9: 19.3 | P9: 20.1 | Q9: 19.08 | R9: 19.3 | S9: 20.1 | T9: 19.08 | U9: 19.3 | V9: 20.1 | W9: 19.08 | X9: 19.3 | Y9: 20.1 | Z9: 19.08 | AA9: 19.3 | AB9: 20.1 | AC9: 19.08 | AD9: 19.3 | AE9: 20.1 | AF9: 19.08
A10: 46287 | B10: 265 | C10: 20.22 | D10: 20.45 | E10: 19.77 | F10: 20.22 | G10: 20.45 | H10: 19.77 | I10: 20.22 | J10: 20.45 | K10: 19.77 | L10: 20.22 | M10: 20.45 | N10: 19.77 | O10: 20.22 | P10: 20.45 | Q10: 19.77 | R10: 20.22 | S10: 20.45 | T10: 19.77 | U10: 20.22 | V10: 20.45 | W10: 19.77 | X10: 20.22 | Y10: 20.45 | Z10: 19.77 | AA10: 20.22 | AB10: 20.45 | AC10: 19.77 | AD10: 20.22 | AE10: 20.45 | AF10: 19.77
A11: 46288 | B11: 266 | C11: 19.91 | D11: 20.07 | E11: 19.66 | F11: 19.91 | G11: 20.07 | H11: 19.66 | I11: 19.91 | J11: 20.07 | K11: 19.66 | L11: 19.91 | M11: 20.07 | N11: 19.66 | O11: 19.91 | P11: 20.07 | Q11: 19.66 | R11: 19.91 | S11: 20.07 | T11: 19.66 | U11: 19.91 | V11: 20.07 | W11: 19.66 | X11: 19.91 | Y11: 20.07 | Z11: 19.66 | AA11: 19.91 | AB11: 20.07 | AC11: 19.66 | AD11: 19.91 | AE11: 20.07 | AF11: 19.66
A12: 46289 | B12: 267 | C12: 19.64 | D12: 20.22 | E12: 19.4 | F12: 19.64 | G12: 20.22 | H12: 19.4 | I12: 19.64 | J12: 20.22 | K12: 19.4 | L12: 19.64 | M12: 20.22 | N12: 19.4 | O12: 19.64 | P12: 20.22 | Q12: 19.4 | R12: 19.64 | S12: 20.22 | T12: 19.4 | U12: 19.64 | V12: 20.22 | W12: 19.4 | X12: 19.64 | Y12: 20.22 | Z12: 19.4 | AA12: 19.64 | AB12: 20.22 | AC12: 19.4 | AD12: 19.64 | AE12: 20.22 | AF12: 19.4
A13: 46290 | B13: 268 | C13: 20.06 | D13: 19.8 | E13: 19.32 | F13: 20.06 | G13: 19.8 | H13: 19.32 | I13: 20.06 | J13: 19.8 | K13: 19.32 | L13: 20.06 | M13: 19.8 | N13: 19.32 | O13: 20.06 | P13: 19.8 | Q13: 19.32 | R13: 20.06 | S13: 19.8 | T13: 19.32 | U13: 20.06 | V13: 19.8 | W13: 19.32 | X13: 20.06 | Y13: 19.8 | Z13: 19.32 | AA13: 20.06 | AB13: 19.8 | AC13: 19.32 | AD13: 20.06 | AE13: 19.8 | AF13: 19.32
A14: 46291 | B14: 269 | C14: 20.13 | D14: 19.65 | E14: 19.35 | F14: 20.13 | G14: 19.65 | H14: 19.35 | I14: 20.13 | J14: 19.65 | K14: 19.35 | L14: 20.13 | M14: 19.65 | N14: 19.35 | O14: 20.13 | P14: 19.65 | Q14: 19.35 | R14: 20.13 | S14: 19.65 | T14: 19.35 | U14: 20.13 | V14: 19.65 | W14: 19.35 | X14: 20.13 | Y14: 19.65 | Z14: 19.35 | AA14: 20.13 | AB14: 19.65 | AC14: 19.35 | AD14: 20.13 | AE14: 19.65 | AF14: 19.35
A15: 46292 | B15: 270 | C15: 19.64 | D15: 19.78 | E15: 19.11 | F15: 19.64 | G15: 19.78 | H15: 19.11 | I15: 19.64 | J15: 19.78 | K15: 19.11 | L15: 19.64 | M15: 19.78 | N15: 19.11 | O15: 19.64 | P15: 19.78 | Q15: 19.11 | R15: 19.64 | S15: 19.78 | T15: 19.11 | U15: 19.64 | V15: 19.78 | W15: 19.11 | X15: 19.64 | Y15: 19.78 | Z15: 19.11 | AA15: 19.64 | AB15: 19.78 | AC15: 19.11 | AD15: 19.64 | AE15: 19.78 | AF15: 19.11
A16: 46293 | B16: 271 | C16: 19.06 | D16: 19.74 | E16: 18.62 | F16: 16.05 | G16: 19.74 | H16: 16.64 | I16: 19.06 | J16: 19.74 | K16: 18.62 | L16: 16.05 | M16: 19.74 | N16: 16.64 | O16: 19.06 | P16: 19.74 | Q16: 18.62 | R16: 16.05 | S16: 19.74 | T16: 16.64 | U16: 19.06 | V16: 19.74 | W16: 18.62 | X16: 19.06 | Y16: 19.74 | Z16: 18.62 | AA16: 16.95 | AB16: 19.74 | AC16: 17.23 | AD16: 19.06 | AE16: 19.74 | AF16: 18.62
A17: 46294 | B17: 272 | C17: 18.86 | D17: 20.04 | E17: 18.57 | F17: 15.86 | G17: 20.04 | H17: 16.61 | I17: 18.86 | J17: 20.04 | K17: 18.57 | L17: 15.86 | M17: 20.04 | N17: 16.61 | O17: 18.86 | P17: 20.04 | Q17: 18.57 | R17: 15.86 | S17: 20.04 | T17: 16.61 | U17: 18.86 | V17: 20.04 | W17: 18.57 | X17: 18.86 | Y17: 20.04 | Z17: 18.57 | AA17: 16.83 | AB17: 20.04 | AC17: 17.24 | AD17: 18.86 | AE17: 20.04 | AF17: 18.57
... A79: 46356 | B79: 334 | C79: 13.13 | D79: 13.11 | E79: 13.83 | F79: 13.37 | G79: 13.33 | H79: 14 | I79: 13.67 | J79: 13.36 | K79: 14.2 | L79: 13.88 | M79: 13.56 | N79: 14.34 | O79: 13.64 | P79: 13.51 | Q79: 14.18 | R79: 13.85 | S79: 13.69 | T79: 14.32 | U79: 13.33 | V79: 13.21 | W79: 13.97 | X79: 13.85 | Y79: 13.59 | Z79: 14.32 | AA79: 13.58 | AB79: 13.27 | AC79: 14.14 | AD79: 13.77 | AE79: 13.41 | AF79: 14.27

Sheet 2014 °F
C1: NBP | F1: NBP - 38 | I1: PB1 | L1: PB1-38 | O1: PB2 | R1: PB2-38 | U1: PB3 | X1: PB4 | AA1: PB5 | AD1: PB6
A2: Date | B2: JDAY | C2: AveFol | D2: AveWatt | E2: AveHazel | F2: AveFol | G2: AveWatt | H2: AveHazel | I2: AveFol | J2: AveWatt | K2: AveHazel | L2: AveFol | M2: AveWatt | N2: AveHazel | O2: AveFol | P2: AveWatt | Q2: AveHazel | R2: AveFol | S2: AveWatt | T2: AveHazel | U2: AveFol | V2: AveWatt | W2: AveHazel | X2: AveFol | Y2: AveWatt | Z2: AveHazel | AA2: AveFol | AB2: AveWatt | AC2: AveHazel | AD2: AveFol | AE2: AveWatt | AF2: AveHazel
A3: 46280 | B3: 258 | C3: ='2014'!C3*9/5+32 -> 64.58 | E3: ='2014'!E3*9/5+32 -> 65.624 | F3: ='2014'!F3*9/5+32 -> 64.58 | H3: ='2014'!H3*9/5+32 -> 65.624 | I3: ='2014'!I3*9/5+32 -> 64.58 | K3: ='2014'!K3*9/5+32 -> 65.624 | L3: ='2014'!L3*9/5+32 -> 64.58 | N3: ='2014'!N3*9/5+32 -> 65.624 | O3: ='2014'!O3*9/5+32 -> 64.58 | Q3: ='2014'!Q3*9/5+32 -> 65.624 | R3: ='2014'!R3*9/5+32 -> 64.58 | T3: ='2014'!T3*9/5+32 -> 65.624 | U3: ='2014'!U3*9/5+32 -> 64.58 | W3: ='2014'!W3*9/5+32 -> 65.624 | X3: ='2014'!X3*9/5+32 -> 64.58 | Z3: ='2014'!Z3*9/5+32 -> 65.624 | AA3: ='2014'!AA3*9/5+32 -> 64.58 | AC3: ='2014'!AC3*9/5+32 -> 65.624 | AD3: ='2014'!AD3*9/5+32 -> 64.58 | AF3: ='2014'!AF3*9/5+32 -> 65.624
A4: 46281 | B4: 259 | C4: ='2014'!C4*9/5+32 -> 67.928 | E4: ='2014'!E4*9/5+32 -> 67.694 | F4: ='2014'!F4*9/5+32 -> 67.928 | H4: ='2014'!H4*9/5+32 -> 67.694 | I4: ='2014'!I4*9/5+32 -> 67.928 | K4: ='2014'!K4*9/5+32 -> 67.694 | L4: ='2014'!L4*9/5+32 -> 67.928 | N4: ='2014'!N4*9/5+32 -> 67.694 | O4: ='2014'!O4*9/5+32 -> 67.928 | Q4: ='2014'!Q4*9/5+32 -> 67.694 | R4: ='2014'!R4*9/5+32 -> 67.928 | T4: ='2014'!T4*9/5+32 -> 67.694 | U4: ='2014'!U4*9/5+32 -> 67.928 | W4: ='2014'!W4*9/5+32 -> 67.694 | X4: ='2014'!X4*9/5+32 -> 67.928 | Z4: ='2014'!Z4*9/5+32 -> 67.694 | AA4: ='2014'!AA4*9/5+32 -> 67.928 | AC4: ='2014'!AC4*9/5+32 -> 67.694 | AD4: ='2014'!AD4*9/5+32 -> 67.928 | AF4: ='2014'!AF4*9/5+32 -> 67.694
A5: 46282 | B5: 260 | C5: ='2014'!C5*9/5+32 -> 65.21 | E5: ='2014'!E5*9/5+32 -> 65.822 | F5: ='2014'!F5*9/5+32 -> 65.21 | H5: ='2014'!H5*9/5+32 -> 65.822 | I5: ='2014'!I5*9/5+32 -> 65.21 | K5: ='2014'!K5*9/5+32 -> 65.822 | L5: ='2014'!L5*9/5+32 -> 65.21 | N5: ='2014'!N5*9/5+32 -> 65.822 | O5: ='2014'!O5*9/5+32 -> 65.21 | Q5: ='2014'!Q5*9/5+32 -> 65.822 | R5: ='2014'!R5*9/5+32 -> 65.21 | T5: ='2014'!T5*9/5+32 -> 65.822 | U5: ='2014'!U5*9/5+32 -> 65.21 | W5: ='2014'!W5*9/5+32 -> 65.822 | X5: ='2014'!X5*9/5+32 -> 65.21 | Z5: ='2014'!Z5*9/5+32 -> 65.822 | AA5: ='2014'!AA5*9/5+32 -> 65.21 | AC5: ='2014'!AC5*9/5+32 -> 65.822 | AD5: ='2014'!AD5*9/5+32 -> 65.21 | AF5: ='2014'!AF5*9/5+32 -> 65.822
A6: 46283 | B6: 261 | C6: ='2014'!C6*9/5+32 -> 67.604 | D6: ='2014'!D6*9/5+32 -> 67.442 | E6: ='2014'!E6*9/5+32 -> 67.316 | F6: ='2014'!F6*9/5+32 -> 67.604 | G6: ='2014'!G6*9/5+32 -> 67.442 | H6: ='2014'!H6*9/5+32 -> 67.316 | I6: ='2014'!I6*9/5+32 -> 67.604 | J6: ='2014'!J6*9/5+32 -> 67.442 | ... AF6: ='2014'!AF6*9/5+32 -> 67.316
A7: 46284 | B7: 262 | C7: ='2014'!C7*9/5+32 -> 68.054 | D7: ='2014'!D7*9/5+32 -> 68.774 | E7: ='2014'!E7*9/5+32 -> 67.496 | F7: ='2014'!F7*9/5+32 -> 68.054 | G7: ='2014'!G7*9/5+32 -> 68.774 | H7: ='2014'!H7*9/5+32 -> 67.496 | I7: ='2014'!I7*9/5+32 -> 68.054 | J7: ='2014'!J7*9/5+32 -> 68.774 | ... AF7: ='2014'!AF7*9/5+32 -> 67.496
A8: 46285 | B8: 263 | C8: ='2014'!C8*9/5+32 -> 65.696 | D8: ='2014'!D8*9/5+32 -> 67.928 | E8: ='2014'!E8*9/5+32 -> 66.056 | F8: ='2014'!F8*9/5+32 -> 65.696 | G8: ='2014'!G8*9/5+32 -> 67.928 | H8: ='2014'!H8*9/5+32 -> 66.056 | I8: ='2014'!I8*9/5+32 -> 65.696 | J8: ='2014'!J8*9/5+32 -> 67.928 | ... AF8: ='2014'!AF8*9/5+32 -> 66.056
A9: 46286 | B9: 264 | C9: ='2014'!C9*9/5+32 -> 66.74 | D9: ='2014'!D9*9/5+32 -> 68.18 | E9: ='2014'!E9*9/5+32 -> 66.344 | F9: ='2014'!F9*9/5+32 -> 66.74 | G9: ='2014'!G9*9/5+32 -> 68.18 | H9: ='2014'!H9*9/5+32 -> 66.344 | I9: ='2014'!I9*9/5+32 -> 66.74 | J9: ='2014'!J9*9/5+32 -> 68.18 | ... AF9: ='2014'!AF9*9/5+32 -> 66.344
A10: 46287 | B10: 265 | C10: ='2014'!C10*9/5+32 -> 68.396 | D10: ='2014'!D10*9/5+32 -> 68.81 | E10: ='2014'!E10*9/5+32 -> 67.586 | F10: ='2014'!F10*9/5+32 -> 68.396 | G10: ='2014'!G10*9/5+32 -> 68.81 | H10: ='2014'!H10*9/5+32 -> 67.586 | I10: ='2014'!I10*9/5+32 -> 68.396 | J10: ='2014'!J10*9/5+32 -> 68.81 | ... AF10: ='2014'!AF10*9/5+32 -> 67.586
A11: 46288 | B11: 266 | C11: ='2014'!C11*9/5+32 -> 67.838 | D11: ='2014'!D11*9/5+32 -> 68.126 | E11: ='2014'!E11*9/5+32 -> 67.388 | F11: ='2014'!F11*9/5+32 -> 67.838 | G11: ='2014'!G11*9/5+32 -> 68.126 | H11: ='2014'!H11*9/5+32 -> 67.388 | I11: ='2014'!I11*9/5+32 -> 67.838 | J11: ='2014'!J11*9/5+32 -> 68.126 | ... AF11: ='2014'!AF11*9/5+32 -> 67.388
A12: 46289 | B12: 267 | C12: ='2014'!C12*9/5+32 -> 67.352 | D12: ='2014'!D12*9/5+32 -> 68.396 | E12: ='2014'!E12*9/5+32 -> 66.92 | F12: ='2014'!F12*9/5+32 -> 67.352 | G12: ='2014'!G12*9/5+32 -> 68.396 | H12: ='2014'!H12*9/5+32 -> 66.92 | I12: ='2014'!I12*9/5+32 -> 67.352 | J12: ='2014'!J12*9/5+32 -> 68.396 | ... AF12: ='2014'!AF12*9/5+32 -> 66.92
A13: 46290 | B13: 268 | C13: ='2014'!C13*9/5+32 -> 68.108 | D13: ='2014'!D13*9/5+32 -> 67.64 | E13: ='2014'!E13*9/5+32 -> 66.776 | F13: ='2014'!F13*9/5+32 -> 68.108 | G13: ='2014'!G13*9/5+32 -> 67.64 | H13: ='2014'!H13*9/5+32 -> 66.776 | I13: ='2014'!I13*9/5+32 -> 68.108 | J13: ='2014'!J13*9/5+32 -> 67.64 | ... AF13: ='2014'!AF13*9/5+32 -> 66.776
A14: 46291 | B14: 269 | C14: ='2014'!C14*9/5+32 -> 68.234 | D14: ='2014'!D14*9/5+32 -> 67.37 | E14: ='2014'!E14*9/5+32 -> 66.83 | F14: ='2014'!F14*9/5+32 -> 68.234 | G14: ='2014'!G14*9/5+32 -> 67.37 | H14: ='2014'!H14*9/5+32 -> 66.83 | I14: ='2014'!I14*9/5+32 -> 68.234 | J14: ='2014'!J14*9/5+32 -> 67.37 | ... AF14: ='2014'!AF14*9/5+32 -> 66.83
A15: 46292 | B15: 270 | C15: ='2014'!C15*9/5+32 -> 67.352 | D15: ='2014'!D15*9/5+32 -> 67.604 | E15: ='2014'!E15*9/5+32 -> 66.398 | F15: ='2014'!F15*9/5+32 -> 67.352 | G15: ='2014'!G15*9/5+32 -> 67.604 | H15: ='2014'!H15*9/5+32 -> 66.398 | I15: ='2014'!I15*9/5+32 -> 67.352 | J15: ='2014'!J15*9/5+32 -> 67.604 | ... AF15: ='2014'!AF15*9/5+32 -> 66.398
A16: 46293 | B16: 271 | C16: ='2014'!C16*9/5+32 -> 66.308 | D16: ='2014'!D16*9/5+32 -> 67.532 | E16: ='2014'!E16*9/5+32 -> 65.516 | F16: ='2014'!F16*9/5+32 -> 60.89 | G16: ='2014'!G16*9/5+32 -> 67.532 | H16: ='2014'!H16*9/5+32 -> 61.952 | I16: ='2014'!I16*9/5+32 -> 66.308 | J16: ='2014'!J16*9/5+32 -> 67.532 | ... AF16: ='2014'!AF16*9/5+32 -> 65.516
A17: 46294 | B17: 272 | C17: ='2014'!C17*9/5+32 -> 65.948 | D17: ='2014'!D17*9/5+32 -> 68.072 | E17: ='2014'!E17*9/5+32 -> 65.426 | F17: ='2014'!F17*9/5+32 -> 60.548 | G17: ='2014'!G17*9/5+32 -> 68.072 | H17: ='2014'!H17*9/5+32 -> 61.898 | I17: ='2014'!I17*9/5+32 -> 65.948 | J17: ='2014'!J17*9/5+32 -> 68.072 | ... AF17: ='2014'!AF17*9/5+32 -> 65.426
... A79: 46356 | B79: 334 | C79: ='2014'!C79*9/5+32 -> 55.634 | D79: ='2014'!D79*9/5+32 -> 55.598 | E79: ='2014'!E79*9/5+32 -> 56.894 | F79: ='2014'!F79*9/5+32 -> 56.066 | G79: ='2014'!G79*9/5+32 -> 55.994 | H79: ='2014'!H79*9/5+32 -> 57.2 | I79: ='2014'!I79*9/5+32 -> 56.606 | J79: ='2014'!J79*9/5+32 -> 56.048 | ... AF79: ='2014'!AF79*9/5+32 -> 57.686

Sheet 2017
C1: NBP | F1: NBP - 38 | I1: PB1 | L1: PB1-38 | O1: PB2 | R1: PB2-38 | U1: PB3 | X1: PB4 | AA1: PB5 | AD1: PB6
A2: Date | B2: JDAY | C2: AveFol | D2: AveWatt | E2: AveHazel | F2: AveFol | G2: AveWatt | H2: AveHazel | I2: AveFol | J2: AveWatt | K2: AveHazel | L2: AveFol | M2: AveWatt | N2: AveHazel | O2: AveFol | P2: AveWatt | Q2: AveHazel | R2: AveFol | S2: AveWatt | T2: AveHazel | U2: AveFol | V2: AveWatt | W2: AveHazel | X2: AveFol | Y2: AveWatt | Z2: AveHazel | AA2: AveFol | AB2: AveWatt | AC2: AveHazel | AD2: AveFol | AE2: AveWatt | AF2: AveHazel
A3: 46280 | B3: 258 | C3: 18.2 | E3: 18.41 | F3: 18.2 | H3: 18.41 | I3: 18.2 | K3: 18.41 | L3: 18.2 | N3: 18.41 | O3: 18.2 | Q3: 18.41 | R3: 18.2 | T3: 18.41 | U3: 18.2 | W3: 18.41 | X3: 18.2 | Z3: 18.41 | AA3: 18.2 | AC3: 18.41 | AD3: 18.2 | AF3: 18.41
A4: 46281 | B4: 259 | C4: 19.76 | E4: 19.53 | F4: 19.76 | H4: 19.53 | I4: 19.76 | K4: 19.53 | L4: 19.76 | N4: 19.53 | O4: 19.76 | Q4: 19.53 | R4: 19.76 | T4: 19.53 | U4: 19.76 | W4: 19.53 | X4: 19.76 | Z4: 19.53 | AA4: 19.76 | AC4: 19.53 | AD4: 19.76 | AF4: 19.53
A5: 46282 | B5: 260 | C5: 19.79 | E5: 19.52 | F5: 19.79 | H5: 19.52 | I5: 19.79 | K5: 19.52 | L5: 19.79 | N5: 19.52 | O5: 19.79 | Q5: 19.52 | R5: 19.79 | T5: 19.52 | U5: 19.79 | W5: 19.52 | X5: 19.79 | Z5: 19.52 | AA5: 19.79 | AC5: 19.52 | AD5: 19.79 | AF5: 19.52
A6: 46283 | B6: 261 | C6: 20.22 | D6: 19.23 | E6: 19.71 | F6: 20.22 | G6: 19.23 | H6: 19.71 | I6: 20.22 | J6: 19.23 | K6: 19.71 | L6: 20.22 | M6: 19.23 | N6: 19.71 | O6: 20.22 | P6: 19.23 | Q6: 19.71 | R6: 20.22 | S6: 19.23 | T6: 19.71 | U6: 20.22 | V6: 19.23 | W6: 19.71 | X6: 20.22 | Y6: 19.23 | Z6: 19.71 | AA6: 20.22 | AB6: 19.23 | AC6: 19.71 | AD6: 20.22 | AE6: 19.23 | AF6: 19.71
A7: 46284 | B7: 262 | C7: 19.4 | D7: 19.71 | E7: 19.02 | F7: 19.4 | G7: 19.71 | H7: 19.02 | I7: 19.4 | J7: 19.71 | K7: 19.02 | L7: 19.4 | M7: 19.71 | N7: 19.02 | O7: 19.4 | P7: 19.71 | Q7: 19.02 | R7: 19.4 | S7: 19.71 | T7: 19.02 | U7: 19.4 | V7: 19.71 | W7: 19.02 | X7: 19.4 | Y7: 19.71 | Z7: 19.02 | AA7: 19.4 | AB7: 19.71 | AC7: 19.02 | AD7: 19.4 | AE7: 19.71 | AF7: 19.02
A8: 46285 | B8: 263 | C8: 20.15 | D8: 19.65 | E8: 19.48 | F8: 20.15 | G8: 19.65 | H8: 19.48 | I8: 20.15 | J8: 19.65 | K8: 19.48 | L8: 20.15 | M8: 19.65 | N8: 19.48 | O8: 20.15 | P8: 19.65 | Q8: 19.48 | R8: 20.15 | S8: 19.65 | T8: 19.48 | U8: 20.15 | V8: 19.65 | W8: 19.48 | X8: 20.15 | Y8: 19.65 | Z8: 19.48 | AA8: 20.15 | AB8: 19.65 | AC8: 19.48 | AD8: 20.15 | AE8: 19.65 | AF8: 19.48
A9: 46286 | B9: 264 | C9: 20.19 | D9: 19.59 | E9: 19.38 | F9: 20.19 | G9: 19.59 | H9: 19.38 | I9: 20.19 | J9: 19.59 | K9: 19.38 | L9: 20.19 | M9: 19.59 | N9: 19.38 | O9: 20.19 | P9: 19.59 | Q9: 19.38 | R9: 20.19 | S9: 19.59 | T9: 19.38 | U9: 20.19 | V9: 19.59 | W9: 19.38 | X9: 20.19 | Y9: 19.59 | Z9: 19.38 | AA9: 20.19 | AB9: 19.59 | AC9: 19.38 | AD9: 20.19 | AE9: 19.59 | AF9: 19.38
A10: 46287 | B10: 265 | C10: 19.77 | D10: 19.17 | E10: 19.08 | F10: 19.77 | G10: 19.17 | H10: 19.08 | I10: 19.77 | J10: 19.17 | K10: 19.08 | L10: 19.77 | M10: 19.17 | N10: 19.08 | O10: 19.77 | P10: 19.17 | Q10: 19.08 | R10: 19.77 | S10: 19.17 | T10: 19.08 | U10: 19.77 | V10: 19.17 | W10: 19.08 | X10: 19.77 | Y10: 19.17 | Z10: 19.08 | AA10: 19.77 | AB10: 19.17 | AC10: 19.08 | AD10: 19.77 | AE10: 19.17 | AF10: 19.08
A11: 46288 | B11: 266 | C11: 19.37 | D11: 19.77 | E11: 18.88 | F11: 19.37 | G11: 19.77 | H11: 18.88 | I11: 19.37 | J11: 19.77 | K11: 18.88 | L11: 19.37 | M11: 19.77 | N11: 18.88 | O11: 19.37 | P11: 19.77 | Q11: 18.88 | R11: 19.37 | S11: 19.77 | T11: 18.88 | U11: 19.37 | V11: 19.77 | W11: 18.88 | X11: 19.37 | Y11: 19.77 | Z11: 18.88 | AA11: 19.37 | AB11: 19.77 | AC11: 18.88 | AD11: 19.37 | AE11: 19.77 | AF11: 18.88
A12: 46289 | B12: 267 | C12: 18.74 | D12: 19.89 | E12: 18.49 | F12: 18.74 | G12: 19.89 | H12: 18.49 | I12: 18.74 | J12: 19.89 | K12: 18.49 | L12: 18.74 | M12: 19.89 | N12: 18.49 | O12: 18.74 | P12: 19.89 | Q12: 18.49 | R12: 18.74 | S12: 19.89 | T12: 18.49 | U12: 18.74 | V12: 19.89 | W12: 18.49 | X12: 18.74 | Y12: 19.89 | Z12: 18.49 | AA12: 18.74 | AB12: 19.89 | AC12: 18.49 | AD12: 18.74 | AE12: 19.89 | AF12: 18.49
A13: 46290 | B13: 268 | C13: 18.66 | D13: 19.94 | E13: 18.52 | F13: 18.66 | G13: 19.94 | H13: 18.52 | I13: 18.66 | J13: 19.94 | K13: 18.52 | L13: 18.66 | M13: 19.94 | N13: 18.52 | O13: 18.66 | P13: 19.94 | Q13: 18.52 | R13: 18.66 | S13: 19.94 | T13: 18.52 | U13: 18.66 | V13: 19.94 | W13: 18.52 | X13: 18.66 | Y13: 19.94 | Z13: 18.52 | AA13: 18.66 | AB13: 19.94 | AC13: 18.52 | AD13: 18.66 | AE13: 19.94 | AF13: 18.52
A14: 46291 | B14: 269 | C14: 19.18 | D14: 20.44 | E14: 19.12 | F14: 19.18 | G14: 20.44 | H14: 19.12 | I14: 19.18 | J14: 20.44 | K14: 19.12 | L14: 19.18 | M14: 20.44 | N14: 19.12 | O14: 19.18 | P14: 20.44 | Q14: 19.12 | R14: 19.18 | S14: 20.44 | T14: 19.12 | U14: 19.18 | V14: 20.44 | W14: 19.12 | X14: 19.18 | Y14: 20.44 | Z14: 19.12 | AA14: 19.18 | AB14: 20.44 | AC14: 19.12 | AD14: 19.18 | AE14: 20.44 | AF14: 19.12
A15: 46292 | B15: 270 | C15: 19.25 | D15: 20.08 | E15: 19.14 | F15: 19.25 | G15: 20.08 | H15: 19.14 | I15: 19.25 | J15: 20.08 | K15: 19.14 | L15: 19.25 | M15: 20.08 | N15: 19.14 | O15: 19.25 | P15: 20.08 | Q15: 19.14 | R15: 19.25 | S15: 20.08 | T15: 19.14 | U15: 19.25 | V15: 20.08 | W15: 19.14 | X15: 19.25 | Y15: 20.08 | Z15: 19.14 | AA15: 19.25 | AB15: 20.08 | AC15: 19.14 | AD15: 19.25 | AE15: 20.08 | AF15: 19.14
A16: 46293 | B16: 271 | C16: 19.29 | D16: 20 | E16: 19.14 | F16: 19.03 | G16: 20 | H16: 18.97 | I16: 19.29 | J16: 20 | K16: 19.14 | L16: 19.03 | M16: 20 | N16: 18.97 | O16: 19.29 | P16: 20 | Q16: 19.14 | R16: 19.03 | S16: 20 | T16: 18.97 | U16: 19.29 | V16: 20 | W16: 19.14 | X16: 19.29 | Y16: 20 | Z16: 19.14 | AA16: 19.11 | AB16: 20 | AC16: 19.02 | AD16: 19.29 | AE16: 20 | AF16: 19.14
A17: 46294 | B17: 272 | C17: 19.41 | D17: 19.97 | E17: 19.09 | F17: 17.36 | G17: 19.97 | H17: 17.75 | I17: 19.41 | J17: 19.97 | K17: 19.09 | L17: 17.36 | M17: 19.97 | N17: 17.75 | O17: 19.41 | P17: 19.97 | Q17: 19.09 | R17: 17.36 | S17: 19.97 | T17: 17.75 | U17: 19.41 | V17: 19.97 | W17: 19.09 | X17: 19.41 | Y17: 19.97 | Z17: 19.09 | AA17: 18.37 | AB17: 19.97 | AC17: 18.41 | AD17: 19.41 | AE17: 19.97 | AF17: 19.09
... A79: 46356 | B79: 334 | C79: 13.12 | D79: 12.55 | E79: 13.52 | F79: 13.17 | G79: 12.58 | H79: 13.55 | I79: 13.53 | J79: 12.83 | K79: 13.8 | L79: 13.59 | M79: 12.87 | N79: 13.84 | O79: 13.48 | P79: 12.96 | Q79: 13.76 | R79: 13.52 | S79: 13.01 | T79: 13.8 | U79: 13.25 | V79: 12.66 | W79: 13.61 | X79: 13.66 | Y79: 12.87 | Z79: 13.89 | AA79: 13.37 | AB79: 12.68 | AC79: 13.69 | AD79: 13.6 | AE79: 12.8 | AF79: 13.85

Sheet 2017 °F
C1: NBP | F1: NBP - 38 | I1: PB1 | L1: PB1-38 | O1: PB2 | R1: PB2-38 | U1: PB3 | X1: PB4 | AA1: PB5 | AD1: PB6
A2: Date | B2: JDAY | C2: AveFol | D2: AveWatt | E2: AveHazel | F2: AveFol | G2: AveWatt | H2: AveHazel | I2: AveFol | J2: AveWatt | K2: AveHazel | L2: AveFol | M2: AveWatt | N2: AveHazel | O2: AveFol | P2: AveWatt | Q2: AveHazel | R2: AveFol | S2: AveWatt | T2: AveHazel | U2: AveFol | V2: AveWatt | W2: AveHazel | X2: AveFol | Y2: AveWatt | Z2: AveHazel | AA2: AveFol | AB2: AveWatt | AC2: AveHazel | AD2: AveFol | AE2: AveWatt | AF2: AveHazel
A3: 46280 | B3: 258 | C3: ='2017'!C3*9/5+32 -> 64.76 | E3: ='2017'!E3*9/5+32 -> 65.138 | F3: ='2017'!F3*9/5+32 -> 64.76 | H3: ='2017'!H3*9/5+32 -> 65.138 | I3: ='2017'!I3*9/5+32 -> 64.76 | K3: ='2017'!K3*9/5+32 -> 65.138 | L3: ='2017'!L3*9/5+32 -> 64.76 | N3: ='2017'!N3*9/5+32 -> 65.138 | O3: ='2017'!O3*9/5+32 -> 64.76 | Q3: ='2017'!Q3*9/5+32 -> 65.138 | R3: ='2017'!R3*9/5+32 -> 64.76 | T3: ='2017'!T3*9/5+32 -> 65.138 | U3: ='2017'!U3*9/5+32 -> 64.76 | W3: ='2017'!W3*9/5+32 -> 65.138 | X3: ='2017'!X3*9/5+32 -> 64.76 | Z3: ='2017'!Z3*9/5+32 -> 65.138 | AA3: ='2017'!AA3*9/5+32 -> 64.76 | AC3: ='2017'!AC3*9/5+32 -> 65.138 | AD3: ='2017'!AD3*9/5+32 -> 64.76 | AF3: ='2017'!AF3*9/5+32 -> 65.138
A4: 46281 | B4: 259 | C4: ='2017'!C4*9/5+32 -> 67.568 | E4: ='2017'!E4*9/5+32 -> 67.154 | F4: ='2017'!F4*9/5+32 -> 67.568 | H4: ='2017'!H4*9/5+32 -> 67.154 | I4: ='2017'!I4*9/5+32 -> 67.568 | K4: ='2017'!K4*9/5+32 -> 67.154 | L4: ='2017'!L4*9/5+32 -> 67.568 | N4: ='2017'!N4*9/5+32 -> 67.154 | O4: ='2017'!O4*9/5+32 -> 67.568 | Q4: ='2017'!Q4*9/5+32 -> 67.154 | R4: ='2017'!R4*9/5+32 -> 67.568 | T4: ='2017'!T4*9/5+32 -> 67.154 | U4: ='2017'!U4*9/5+32 -> 67.568 | W4: ='2017'!W4*9/5+32 -> 67.154 | X4: ='2017'!X4*9/5+32 -> 67.568 | Z4: ='2017'!Z4*9/5+32 -> 67.154 | AA4: ='2017'!AA4*9/5+32 -> 67.568 | AC4: ='2017'!AC4*9/5+32 -> 67.154 | AD4: ='2017'!AD4*9/5+32 -> 67.568 | AF4: ='2017'!AF4*9/5+32 -> 67.154
A5: 46282 | B5: 260 | C5: ='2017'!C5*9/5+32 -> 67.622 | E5: ='2017'!E5*9/5+32 -> 67.136 | F5: ='2017'!F5*9/5+32 -> 67.622 | H5: ='2017'!H5*9/5+32 -> 67.136 | I5: ='2017'!I5*9/5+32 -> 67.622 | K5: ='2017'!K5*9/5+32 -> 67.136 | L5: ='2017'!L5*9/5+32 -> 67.622 | N5: ='2017'!N5*9/5+32 -> 67.136 | O5: ='2017'!O5*9/5+32 -> 67.622 | Q5: ='2017'!Q5*9/5+32 -> 67.136 | R5: ='2017'!R5*9/5+32 -> 67.622 | T5: ='2017'!T5*9/5+32 -> 67.136 | U5: ='2017'!U5*9/5+32 -> 67.622 | W5: ='2017'!W5*9/5+32 -> 67.136 | X5: ='2017'!X5*9/5+32 -> 67.622 | Z5: ='2017'!Z5*9/5+32 -> 67.136 | AA5: ='2017'!AA5*9/5+32 -> 67.622 | AC5: ='2017'!AC5*9/5+32 -> 67.136 | AD5: ='2017'!AD5*9/5+32 -> 67.622 | AF5: ='2017'!AF5*9/5+32 -> 67.136
A6: 46283 | B6: 261 | C6: ='2017'!C6*9/5+32 -> 68.396 | D6: ='2017'!D6*9/5+32 -> 66.614 | E6: ='2017'!E6*9/5+32 -> 67.478 | F6: ='2017'!F6*9/5+32 -> 68.396 | G6: ='2017'!G6*9/5+32 -> 66.614 | H6: ='2017'!H6*9/5+32 -> 67.478 | I6: ='2017'!I6*9/5+32 -> 68.396 | J6: ='2017'!J6*9/5+32 -> 66.614 | ... AF6: ='2017'!AF6*9/5+32 -> 67.478
A7: 46284 | B7: 262 | C7: ='2017'!C7*9/5+32 -> 66.92 | D7: ='2017'!D7*9/5+32 -> 67.478 | E7: ='2017'!E7*9/5+32 -> 66.236 | F7: ='2017'!F7*9/5+32 -> 66.92 | G7: ='2017'!G7*9/5+32 -> 67.478 | H7: ='2017'!H7*9/5+32 -> 66.236 | I7: ='2017'!I7*9/5+32 -> 66.92 | J7: ='2017'!J7*9/5+32 -> 67.478 | ... AF7: ='2017'!AF7*9/5+32 -> 66.236
A8: 46285 | B8: 263 | C8: ='2017'!C8*9/5+32 -> 68.27 | D8: ='2017'!D8*9/5+32 -> 67.37 | E8: ='2017'!E8*9/5+32 -> 67.064 | F8: ='2017'!F8*9/5+32 -> 68.27 | G8: ='2017'!G8*9/5+32 -> 67.37 | H8: ='2017'!H8*9/5+32 -> 67.064 | I8: ='2017'!I8*9/5+32 -> 68.27 | J8: ='2017'!J8*9/5+32 -> 67.37 | ... AF8: ='2017'!AF8*9/5+32 -> 67.064
A9: 46286 | B9: 264 | C9: ='2017'!C9*9/5+32 -> 68.342 | D9: ='2017'!D9*9/5+32 -> 67.262 | E9: ='2017'!E9*9/5+32 -> 66.884 | F9: ='2017'!F9*9/5+32 -> 68.342 | G9: ='2017'!G9*9/5+32 -> 67.262 | H9: ='2017'!H9*9/5+32 -> 66.884 | I9: ='2017'!I9*9/5+32 -> 68.342 | J9: ='2017'!J9*9/5+32 -> 67.262 | ... AF9: ='2017'!AF9*9/5+32 -> 66.884
A10: 46287 | B10: 265 | C10: ='2017'!C10*9/5+32 -> 67.586 | D10: ='2017'!D10*9/5+32 -> 66.506 | E10: ='2017'!E10*9/5+32 -> 66.344 | F10: ='2017'!F10*9/5+32 -> 67.586 | G10: ='2017'!G10*9/5+32 -> 66.506 | H10: ='2017'!H10*9/5+32 -> 66.344 | I10: ='2017'!I10*9/5+32 -> 67.586 | J10: ='2017'!J10*9/5+32 -> 66.506 | ... AF10: ='2017'!AF10*9/5+32 -> 66.344
A11: 46288 | B11: 266 | C11: ='2017'!C11*9/5+32 -> 66.866 | D11: ='2017'!D11*9/5+32 -> 67.586 | E11: ='2017'!E11*9/5+32 -> 65.984 | F11: ='2017'!F11*9/5+32 -> 66.866 | G11: ='2017'!G11*9/5+32 -> 67.586 | H11: ='2017'!H11*9/5+32 -> 65.984 | I11: ='2017'!I11*9/5+32 -> 66.866 | J11: ='2017'!J11*9/5+32 -> 67.586 | ... AF11: ='2017'!AF11*9/5+32 -> 65.984
A12: 46289 | B12: 267 | C12: ='2017'!C12*9/5+32 -> 65.732 | D12: ='2017'!D12*9/5+32 -> 67.802 | E12: ='2017'!E12*9/5+32 -> 65.282 | F12: ='2017'!F12*9/5+32 -> 65.732 | G12: ='2017'!G12*9/5+32 -> 67.802 | H12: ='2017'!H12*9/5+32 -> 65.282 | I12: ='2017'!I12*9/5+32 -> 65.732 | J12: ='2017'!J12*9/5+32 -> 67.802 | ... AF12: ='2017'!AF12*9/5+32 -> 65.282
A13: 46290 | B13: 268 | C13: ='2017'!C13*9/5+32 -> 65.588 | D13: ='2017'!D13*9/5+32 -> 67.892 | E13: ='2017'!E13*9/5+32 -> 65.336 | F13: ='2017'!F13*9/5+32 -> 65.588 | G13: ='2017'!G13*9/5+32 -> 67.892 | H13: ='2017'!H13*9/5+32 -> 65.336 | I13: ='2017'!I13*9/5+32 -> 65.588 | J13: ='2017'!J13*9/5+32 -> 67.892 | ... AF13: ='2017'!AF13*9/5+32 -> 65.336
A14: 46291 | B14: 269 | C14: ='2017'!C14*9/5+32 -> 66.524 | D14: ='2017'!D14*9/5+32 -> 68.792 | E14: ='2017'!E14*9/5+32 -> 66.416 | F14: ='2017'!F14*9/5+32 -> 66.524 | G14: ='2017'!G14*9/5+32 -> 68.792 | H14: ='2017'!H14*9/5+32 -> 66.416 | I14: ='2017'!I14*9/5+32 -> 66.524 | J14: ='2017'!J14*9/5+32 -> 68.792 | ... AF14: ='2017'!AF14*9/5+32 -> 66.416
A15: 46292 | B15: 270 | C15: ='2017'!C15*9/5+32 -> 66.65 | D15: ='2017'!D15*9/5+32 -> 68.144 | E15: ='2017'!E15*9/5+32 -> 66.452 | F15: ='2017'!F15*9/5+32 -> 66.65 | G15: ='2017'!G15*9/5+32 -> 68.144 | H15: ='2017'!H15*9/5+32 -> 66.452 | I15: ='2017'!I15*9/5+32 -> 66.65 | J15: ='2017'!J15*9/5+32 -> 68.144 | ... AF15: ='2017'!AF15*9/5+32 -> 66.452
A16: 46293 | B16: 271 | C16: ='2017'!C16*9/5+32 -> 66.722 | D16: ='2017'!D16*9/5+32 -> 68 | E16: ='2017'!E16*9/5+32 -> 66.452 | F16: ='2017'!F16*9/5+32 -> 66.254 | G16: ='2017'!G16*9/5+32 -> 68 | H16: ='2017'!H16*9/5+32 -> 66.146 | I16: ='2017'!I16*9/5+32 -> 66.722 | J16: ='2017'!J16*9/5+32 -> 68 | ... AF16: ='2017'!AF16*9/5+32 -> 66.452
A17: 46294 | B17: 272 | C17: ='2017'!C17*9/5+32 -> 66.938 | D17: ='2017'!D17*9/5+32 -> 67.946 | E17: ='2017'!E17*9/5+32 -> 66.362 | F17: ='2017'!F17*9/5+32 -> 63.248 | G17: ='2017'!G17*9/5+32 -> 67.946 | H17: ='2017'!H17*9/5+32 -> 63.95 | I17: ='2017'!I17*9/5+32 -> 66.938 | J17: ='2017'!J17*9/5+32 -> 67.946 | ... AF17: ='2017'!AF17*9/5+32 -> 66.362
... A79: 46356 | B79: 334 | C79: ='2017'!C79*9/5+32 -> 55.616 | D79: ='2017'!D79*9/5+32 -> 54.59 | E79: ='2017'!E79*9/5+32 -> 56.336 | F79: ='2017'!F79*9/5+32 -> 55.706 | G79: ='2017'!G79*9/5+32 -> 54.644 | H79: ='2017'!H79*9/5+32 -> 56.39 | I79: ='2017'!I79*9/5+32 -> 56.354 | J79: ='2017'!J79*9/5+32 -> 55.094 | ... AF79: ='2017'!AF79*9/5+32 -> 56.93

Sheet 2020
C1: NBP | F1: NBP - 38 | I1: PB1 | L1: PB1-38 | O1: PB2 | R1: PB2-38 | U1: PB3 | X1: PB4 | AA1: PB5 | AD1: PB6
A2: Date | B2: JDAY | C2: AveFol | D2: AveWatt | E2: AveHazel | F2: AveFol | G2: AveWatt | H2: AveHazel | I2: AveFol | J2: AveWatt | K2: AveHazel | L2: AveFol | M2: AveWatt | N2: AveHazel | O2: AveFol | P2: AveWatt | Q2: AveHazel | R2: AveFol | S2: AveWatt | T2: AveHazel | U2: AveFol | V2: AveWatt | W2: AveHazel | X2: AveFol | Y2: AveWatt | Z2: AveHazel | AA2: AveFol | AB2: AveWatt | AC2: AveHazel | AD2: AveFol | AE2: AveWatt | AF2: AveHazel
A3: 46280 | B3: 258 | C3: 18.17 | E3: 18.46 | F3: 18.17 | H3: 18.46 | I3: 18.17 | K3: 18.46 | L3: 18.17 | N3: 18.46 | O3: 18.17 | Q3: 18.46 | R3: 18.17 | T3: 18.46 | U3: 18.17 | W3: 18.46 | X3: 18.17 | Z3: 18.46 | AA3: 18.17 | AC3: 18.46 | AD3: 18.17 | AF3: 18.46
A4: 46281 | B4: 259 | C4: 19.56 | E4: 19.46 | F4: 19.56 | H4: 19.46 | I4: 19.56 | K4: 19.46 | L4: 19.56 | N4: 19.46 | O4: 19.56 | Q4: 19.46 | R4: 19.56 | T4: 19.46 | U4: 19.56 | W4: 19.46 | X4: 19.56 | Z4: 19.46 | AA4: 19.56 | AC4: 19.46 | AD4: 19.56 | AF4: 19.46
A5: 46282 | B5: 260 | C5: 19.37 | E5: 19.34 | F5: 19.37 | H5: 19.34 | I5: 19.37 | K5: 19.34 | L5: 19.37 | N5: 19.34 | O5: 19.37 | Q5: 19.34 | R5: 19.37 | T5: 19.34 | U5: 19.37 | W5: 19.34 | X5: 19.37 | Z5: 19.34 | AA5: 19.37 | AC5: 19.34 | AD5: 19.37 | AF5: 19.34
A6: 46283 | B6: 261 | C6: 18.83 | D6: 19.74 | E6: 18.98 | F6: 18.83 | G6: 19.74 | H6: 18.98 | I6: 18.83 | J6: 19.74 | K6: 18.98 | L6: 18.83 | M6: 19.74 | N6: 18.98 | O6: 18.83 | P6: 19.74 | Q6: 18.98 | R6: 18.83 | S6: 19.74 | T6: 18.98 | U6: 18.83 | V6: 19.74 | W6: 18.98 | X6: 18.83 | Y6: 19.74 | Z6: 18.98 | AA6: 18.83 | AB6: 19.74 | AC6: 18.98 | AD6: 18.83 | AE6: 19.74 | AF6: 18.98
A7: 46284 | B7: 262 | C7: 18.57 | D7: 20.11 | E7: 18.66 | F7: 18.57 | G7: 20.11 | H7: 18.66 | I7: 18.57 | J7: 20.11 | K7: 18.66 | L7: 18.57 | M7: 20.11 | N7: 18.66 | O7: 18.57 | P7: 20.11 | Q7: 18.66 | R7: 18.57 | S7: 20.11 | T7: 18.66 | U7: 18.57 | V7: 20.11 | W7: 18.66 | X7: 18.57 | Y7: 20.11 | Z7: 18.66 | AA7: 18.57 | AB7: 20.11 | AC7: 18.66 | AD7: 18.57 | AE7: 20.11 | AF7: 18.66
A8: 46285 | B8: 263 | C8: 18.89 | D8: 19.99 | E8: 18.86 | F8: 18.89 | G8: 19.99 | H8: 18.86 | I8: 18.89 | J8: 19.99 | K8: 18.86 | L8: 18.89 | M8: 19.99 | N8: 18.86 | O8: 18.89 | P8: 19.99 | Q8: 18.86 | R8: 18.89 | S8: 19.99 | T8: 18.86 | U8: 18.89 | V8: 19.99 | W8: 18.86 | X8: 18.89 | Y8: 19.99 | Z8: 18.86 | AA8: 18.89 | AB8: 19.99 | AC8: 18.86 | AD8: 18.89 | AE8: 19.99 | AF8: 18.86
A9: 46286 | B9: 264 | C9: 18.78 | D9: 19.97 | E9: 18.87 | F9: 18.78 | G9: 19.97 | H9: 18.87 | I9: 18.78 | J9: 19.97 | K9: 18.87 | L9: 18.78 | M9: 19.97 | N9: 18.87 | O9: 18.78 | P9: 19.97 | Q9: 18.87 | R9: 18.78 | S9: 19.97 | T9: 18.87 | U9: 18.78 | V9: 19.97 | W9: 18.87 | X9: 18.78 | Y9: 19.97 | Z9: 18.87 | AA9: 18.78 | AB9: 19.97 | AC9: 18.87 | AD9: 18.78 | AE9: 19.97 | AF9: 18.87
A10: 46287 | B10: 265 | C10: 19.01 | D10: 20.11 | E10: 19.12 | F10: 19.01 | G10: 20.11 | H10: 19.12 | I10: 19.01 | J10: 20.11 | K10: 19.12 | L10: 19.01 | M10: 20.11 | N10: 19.12 | O10: 19.01 | P10: 20.11 | Q10: 19.12 | R10: 19.01 | S10: 20.11 | T10: 19.12 | U10: 19.01 | V10: 20.11 | W10: 19.12 | X10: 19.01 | Y10: 20.11 | Z10: 19.12 | AA10: 19.01 | AB10: 20.11 | AC10: 19.12 | AD10: 19.01 | AE10: 20.11 | AF10: 19.12
A11: 46288 | B11: 266 | C11: 19.6 | D11: 20.13 | E11: 19.44 | F11: 19.6 | G11: 20.13 | H11: 19.44 | I11: 19.6 | J11: 20.13 | K11: 19.44 | L11: 19.6 | M11: 20.13 | N11: 19.44 | O11: 19.6 | P11: 20.13 | Q11: 19.44 | R11: 19.6 | S11: 20.13 | T11: 19.44 | U11: 19.6 | V11: 20.13 | W11: 19.44 | X11: 19.6 | Y11: 20.13 | Z11: 19.44 | AA11: 19.6 | AB11: 20.13 | AC11: 19.44 | AD11: 19.6 | AE11: 20.13 | AF11: 19.44
A12: 46289 | B12: 267 | C12: 19.96 | D12: 19.99 | E12: 19.63 | F12: 19.96 | G12: 19.99 | H12: 19.63 | I12: 19.96 | J12: 19.99 | K12: 19.63 | L12: 19.96 | M12: 19.99 | N12: 19.63 | O12: 19.96 | P12: 19.99 | Q12: 19.63 | R12: 19.96 | S12: 19.99 | T12: 19.63 | U12: 19.96 | V12: 19.99 | W12: 19.63 | X12: 19.96 | Y12: 19.99 | Z12: 19.63 | AA12: 19.96 | AB12: 19.99 | AC12: 19.63 | AD12: 19.96 | AE12: 19.99 | AF12: 19.63
A13: 46290 | B13: 268 | C13: 18.16 | D13: 20.08 | E13: 18.4 | F13: 18.16 | G13: 20.08 | H13: 18.4 | I13: 18.16 | J13: 20.08 | K13: 18.4 | L13: 18.16 | M13: 20.08 | N13: 18.4 | O13: 18.16 | P13: 20.08 | Q13: 18.4 | R13: 18.16 | S13: 20.08 | T13: 18.4 | U13: 18.16 | V13: 20.08 | W13: 18.4 | X13: 18.16 | Y13: 20.08 | Z13: 18.4 | AA13: 18.16 | AB13: 20.08 | AC13: 18.4 | AD13: 18.16 | AE13: 20.08 | AF13: 18.4
A14: 46291 | B14: 269 | C14: 17.62 | D14: 20.13 | E14: 17.93 | F14: 17.62 | G14: 20.13 | H14: 17.93 | I14: 17.62 | J14: 20.13 | K14: 17.93 | L14: 17.62 | M14: 20.13 | N14: 17.93 | O14: 17.62 | P14: 20.13 | Q14: 17.93 | R14: 17.62 | S14: 20.13 | T14: 17.93 | U14: 17.62 | V14: 20.13 | W14: 17.93 | X14: 17.62 | Y14: 20.13 | Z14: 17.93 | AA14: 17.62 | AB14: 20.13 | AC14: 17.93 | AD14: 17.62 | AE14: 20.13 | AF14: 17.93
A15: 46292 | B15: 270 | C15: 17.79 | D15: 20.7 | E15: 18.17 | F15: 17.79 | G15: 20.7 | H15: 18.17 | I15: 17.79 | J15: 20.7 | K15: 18.17 | L15: 17.79 | M15: 20.7 | N15: 18.17 | O15: 17.79 | P15: 20.7 | Q15: 18.17 | R15: 17.79 | S15: 20.7 | T15: 18.17 | U15: 17.79 | V15: 20.7 | W15: 18.17 | X15: 17.79 | Y15: 20.7 | Z15: 18.17 | AA15: 17.79 | AB15: 20.7 | AC15: 18.17 | AD15: 17.79 | AE15: 20.7 | AF15: 18.17
A16: 46293 | B16: 271 | C16: 17.43 | D16: 20.19 | E16: 18.08 | F16: 14.79 | G16: 20.19 | H16: 16.35 | I16: 17.43 | J16: 20.19 | K16: 18.08 | L16: 14.79 | M16: 20.19 | N16: 16.35 | O16: 17.43 | P16: 20.19 | Q16: 18.08 | R16: 14.79 | S16: 20.19 | T16: 16.35 | U16: 17.43 | V16: 20.19 | W16: 18.08 | X16: 17.43 | Y16: 20.19 | Z16: 18.08 | AA16: 15.65 | AB16: 20.19 | AC16: 16.91 | AD16: 17.43 | AE16: 20.19 | AF16: 18.08
A17: 46294 | B17: 272 | C17: 17.45 | D17: 19.97 | E17: 18.11 | F17: 14.54 | G17: 19.97 | H17: 16.21 | I17: 17.45 | J17: 19.97 | K17: 18.11 | L17: 14.54 | M17: 19.97 | N17: 16.21 | O17: 17.45 | P17: 19.97 | Q17: 18.11 | R17: 14.54 | S17: 19.97 | T17: 16.21 | U17: 17.45 | V17: 19.97 | W17: 18.11 | X17: 17.45 | Y17: 19.97 | Z17: 18.11 | AA17: 15.49 | AB17: 19.97 | AC17: 16.83 | AD17: 17.45 | AE17: 19.97 | AF17: 18.11
... A79: 46356 | B79: 334 | C79: 12.18 | D79: 11.56 | E79: 12.68 | F79: 12.35 | G79: 11.76 | H79: 12.79 | I79: 12.83 | J79: 11.93 | K79: 13.12 | L79: 12.94 | M79: 12.06 | N79: 13.19 | O79: 12.78 | P79: 12 | Q79: 13.09 | R79: 12.89 | S79: 12.13 | T79: 13.16 | U79: 12.56 | V79: 11.79 | W79: 12.94 | X79: 12.88 | Y79: 11.96 | Z79: 13.15 | AA79: 12.79 | AB79: 11.88 | AC79: 13.1 | AD79: 12.84 | AE79: 11.9 | AF79: 13.13

Sheet 2020 °F
C1: NBP | F1: NBP - 38 | I1: PB1 | L1: PB1-38 | O1: PB2 | R1: PB2-38 | U1: PB3 | X1: PB4 | AA1: PB5 | AD1: PB6
A2: Date | B2: JDAY | C2: AveFol | D2: AveWatt | E2: AveHazel | F2: AveFol | G2: AveWatt | H2: AveHazel | I2: AveFol | J2: AveWatt | K2: AveHazel | L2: AveFol | M2: AveWatt | N2: AveHazel | O2: AveFol | P2: AveWatt | Q2: AveHazel | R2: AveFol | S2: AveWatt | T2: AveHazel | U2: AveFol | V2: AveWatt | W2: AveHazel | X2: AveFol | Y2: AveWatt | Z2: AveHazel | AA2: AveFol | AB2: AveWatt | AC2: AveHazel | AD2: AveFol | AE2: AveWatt | AF2: AveHazel
A3: 46280 | B3: 258 | C3: ='2020'!C3*9/5+32 -> 64.706 | E3: ='2020'!E3*9/5+32 -> 65.228 | F3: ='2020'!F3*9/5+32 -> 64.706 | H3: ='2020'!H3*9/5+32 -> 65.228 | I3: ='2020'!I3*9/5+32 -> 64.706 | K3: ='2020'!K3*9/5+32 -> 65.228 | L3: ='2020'!L3*9/5+32 -> 64.706 | N3: ='2020'!N3*9/5+32 -> 65.228 | O3: ='2020'!O3*9/5+32 -> 64.706 | Q3: ='2020'!Q3*9/5+32 -> 65.228 | R3: ='2020'!R3*9/5+32 -> 64.706 | T3: ='2020'!T3*9/5+32 -> 65.228 | U3: ='2020'!U3*9/5+32 -> 64.706 | W3: ='2020'!W3*9/5+32 -> 65.228 | X3: ='2020'!X3*9/5+32 -> 64.706 | Z3: ='2020'!Z3*9/5+32 -> 65.228 | AA3: ='2020'!AA3*9/5+32 -> 64.706 | AC3: ='2020'!AC3*9/5+32 -> 65.228 | AD3: ='2020'!AD3*9/5+32 -> 64.706 | AF3: ='2020'!AF3*9/5+32 -> 65.228
A4: 46281 | B4: 259 | C4: ='2020'!C4*9/5+32 -> 67.208 | E4: ='2020'!E4*9/5+32 -> 67.028 | F4: ='2020'!F4*9/5+32 -> 67.208 | H4: ='2020'!H4*9/5+32 -> 67.028 | I4: ='2020'!I4*9/5+32 -> 67.208 | K4: ='2020'!K4*9/5+32 -> 67.028 | L4: ='2020'!L4*9/5+32 -> 67.208 | N4: ='2020'!N4*9/5+32 -> 67.028 | O4: ='2020'!O4*9/5+32 -> 67.208 | Q4: ='2020'!Q4*9/5+32 -> 67.028 | R4: ='2020'!R4*9/5+32 -> 67.208 | T4: ='2020'!T4*9/5+32 -> 67.028 | U4: ='2020'!U4*9/5+32 -> 67.208 | W4: ='2020'!W4*9/5+32 -> 67.028 | X4: ='2020'!X4*9/5+32 -> 67.208 | Z4: ='2020'!Z4*9/5+32 -> 67.028 | AA4: ='2020'!AA4*9/5+32 -> 67.208 | AC4: ='2020'!AC4*9/5+32 -> 67.028 | AD4: ='2020'!AD4*9/5+32 -> 67.208 | AF4: ='2020'!AF4*9/5+32 -> 67.028
A5: 46282 | B5: 260 | C5: ='2020'!C5*9/5+32 -> 66.866 | E5: ='2020'!E5*9/5+32 -> 66.812 | F5: ='2020'!F5*9/5+32 -> 66.866 | H5: ='2020'!H5*9/5+32 -> 66.812 | I5: ='2020'!I5*9/5+32 -> 66.866 | K5: ='2020'!K5*9/5+32 -> 66.812 | L5: ='2020'!L5*9/5+32 -> 66.866 | N5: ='2020'!N5*9/5+32 -> 66.812 | O5: ='2020'!O5*9/5+32 -> 66.866 | Q5: ='2020'!Q5*9/5+32 -> 66.812 | R5: ='2020'!R5*9/5+32 -> 66.866 | T5: ='2020'!T5*9/5+32 -> 66.812 | U5: ='2020'!U5*9/5+32 -> 66.866 | W5: ='2020'!W5*9/5+32 -> 66.812 | X5: ='2020'!X5*9/5+32 -> 66.866 | Z5: ='2020'!Z5*9/5+32 -> 66.812 | AA5: ='2020'!AA5*9/5+32 -> 66.866 | AC5: ='2020'!AC5*9/5+32 -> 66.812 | AD5: ='2020'!AD5*9/5+32 -> 66.866 | AF5: ='2020'!AF5*9/5+32 -> 66.812
A6: 46283 | B6: 261 | C6: ='2020'!C6*9/5+32 -> 65.894 | D6: ='2020'!D6*9/5+32 -> 67.532 | E6: ='2020'!E6*9/5+32 -> 66.164 | F6: ='2020'!F6*9/5+32 -> 65.894 | G6: ='2020'!G6*9/5+32 -> 67.532 | H6: ='2020'!H6*9/5+32 -> 66.164 | I6: ='2020'!I6*9/5+32 -> 65.894 | J6: ='2020'!J6*9/5+32 -> 67.532 | ... AF6: ='2020'!AF6*9/5+32 -> 66.164
A7: 46284 | B7: 262 | C7: ='2020'!C7*9/5+32 -> 65.426 | D7: ='2020'!D7*9/5+32 -> 68.198 | E7: ='2020'!E7*9/5+32 -> 65.588 | F7: ='2020'!F7*9/5+32 -> 65.426 | G7: ='2020'!G7*9/5+32 -> 68.198 | H7: ='2020'!H7*9/5+32 -> 65.588 | I7: ='2020'!I7*9/5+32 -> 65.426 | J7: ='2020'!J7*9/5+32 -> 68.198 | ... AF7: ='2020'!AF7*9/5+32 -> 65.588
A8: 46285 | B8: 263 | C8: ='2020'!C8*9/5+32 -> 66.002 | D8: ='2020'!D8*9/5+32 -> 67.982 | E8: ='2020'!E8*9/5+32 -> 65.948 | F8: ='2020'!F8*9/5+32 -> 66.002 | G8: ='2020'!G8*9/5+32 -> 67.982 | H8: ='2020'!H8*9/5+32 -> 65.948 | I8: ='2020'!I8*9/5+32 -> 66.002 | J8: ='2020'!J8*9/5+32 -> 67.982 | ... AF8: ='2020'!AF8*9/5+32 -> 65.948
A9: 46286 | B9: 264 | C9: ='2020'!C9*9/5+32 -> 65.804 | D9: ='2020'!D9*9/5+32 -> 67.946 | E9: ='2020'!E9*9/5+32 -> 65.966 | F9: ='2020'!F9*9/5+32 -> 65.804 | G9: ='2020'!G9*9/5+32 -> 67.946 | H9: ='2020'!H9*9/5+32 -> 65.966 | I9: ='2020'!I9*9/5+32 -> 65.804 | J9: ='2020'!J9*9/5+32 -> 67.946 | ... AF9: ='2020'!AF9*9/5+32 -> 65.966
A10: 46287 | B10: 265 | C10: ='2020'!C10*9/5+32 -> 66.218 | D10: ='2020'!D10*9/5+32 -> 68.198 | E10: ='2020'!E10*9/5+32 -> 66.416 | F10: ='2020'!F10*9/5+32 -> 66.218 | G10: ='2020'!G10*9/5+32 -> 68.198 | H10: ='2020'!H10*9/5+32 -> 66.416 | I10: ='2020'!I10*9/5+32 -> 66.218 | J10: ='2020'!J10*9/5+32 -> 68.198 | ... AF10: ='2020'!AF10*9/5+32 -> 66.416
A11: 46288 | B11: 266 | C11: ='2020'!C11*9/5+32 -> 67.28 | D11: ='2020'!D11*9/5+32 -> 68.234 | E11: ='2020'!E11*9/5+32 -> 66.992 | F11: ='2020'!F11*9/5+32 -> 67.28 | G11: ='2020'!G11*9/5+32 -> 68.234 | H11: ='2020'!H11*9/5+32 -> 66.992 | I11: ='2020'!I11*9/5+32 -> 67.28 | J11: ='2020'!J11*9/5+32 -> 68.234 | ... AF11: ='2020'!AF11*9/5+32 -> 66.992
A12: 46289 | B12: 267 | C12: ='2020'!C12*9/5+32 -> 67.928 | D12: ='2020'!D12*9/5+32 -> 67.982 | E12: ='2020'!E12*9/5+32 -> 67.334 | F12: ='2020'!F12*9/5+32 -> 67.928 | G12: ='2020'!G12*9/5+32 -> 67.982 | H12: ='2020'!H12*9/5+32 -> 67.334 | I12: ='2020'!I12*9/5+32 -> 67.928 | J12: ='2020'!J12*9/5+32 -> 67.982 | ... AF12: ='2020'!AF12*9/5+32 -> 67.334
A13: 46290 | B13: 268 | C13: ='2020'!C13*9/5+32 -> 64.688 | D13: ='2020'!D13*9/5+32 -> 68.144 | E13: ='2020'!E13*9/5+32 -> 65.12 | F13: ='2020'!F13*9/5+32 -> 64.688 | G13: ='2020'!G13*9/5+32 -> 68.144 | H13: ='2020'!H13*9/5+32 -> 65.12 | I13: ='2020'!I13*9/5+32 -> 64.688 | J13: ='2020'!J13*9/5+32 -> 68.144 | ... AF13: ='2020'!AF13*9/5+32 -> 65.12
A14: 46291 | B14: 269 | C14: ='2020'!C14*9/5+32 -> 63.716 | D14: ='2020'!D14*9/5+32 -> 68.234 | E14: ='2020'!E14*9/5+32 -> 64.274 | F14: ='2020'!F14*9/5+32 -> 63.716 | G14: ='2020'!G14*9/5+32 -> 68.234 | H14: ='2020'!H14*9/5+32 -> 64.274 | I14: ='2020'!I14*9/5+32 -> 63.716 | J14: ='2020'!J14*9/5+32 -> 68.234 | ... AF14: ='2020'!AF14*9/5+32 -> 64.274
A15: 46292 | B15: 270 | C15: ='2020'!C15*9/5+32 -> 64.022 | D15: ='2020'!D15*9/5+32 -> 69.26 | E15: ='2020'!E15*9/5+32 -> 64.706 | F15: ='2020'!F15*9/5+32 -> 64.022 | G15: ='2020'!G15*9/5+32 -> 69.26 | H15: ='2020'!H15*9/5+32 -> 64.706 | I15: ='2020'!I15*9/5+32 -> 64.022 | J15: ='2020'!J15*9/5+32 -> 69.26 | ... AF15: ='2020'!AF15*9/5+32 -> 64.706
A16: 46293 | B16: 271 | C16: ='2020'!C16*9/5+32 -> 63.374 | D16: ='2020'!D16*9/5+32 -> 68.342 | E16: ='2020'!E16*9/5+32 -> 64.544 | F16: ='2020'!F16*9/5+32 -> 58.622 | G16: ='2020'!G16*9/5+32 -> 68.342 | H16: ='2020'!H16*9/5+32 -> 61.43 | I16: ='2020'!I16*9/5+32 -> 63.374 | J16: ='2020'!J16*9/5+32 -> 68.342 | ... AF16: ='2020'!AF16*9/5+32 -> 64.544
A17: 46294 | B17: 272 | C17: ='2020'!C17*9/5+32 -> 63.41 | D17: ='2020'!D17*9/5+32 -> 67.946 | E17: ='2020'!E17*9/5+32 -> 64.598 | F17: ='2020'!F17*9/5+32 -> 58.172 | G17: ='2020'!G17*9/5+32 -> 67.946 | H17: ='2020'!H17*9/5+32 -> 61.178 | I17: ='2020'!I17*9/5+32 -> 63.41 | J17: ='2020'!J17*9/5+32 -> 67.946 | ... AF17: ='2020'!AF17*9/5+32 -> 64.598
... A79: 46356 | B79: 334 | C79: ='2020'!C79*9/5+32 -> 53.924 | D79: ='2020'!D79*9/5+32 -> 52.808 | E79: ='2020'!E79*9/5+32 -> 54.824 | F79: ='2020'!F79*9/5+32 -> 54.23 | G79: ='2020'!G79*9/5+32 -> 53.168 | H79: ='2020'!H79*9/5+32 -> 55.022 | I79: ='2020'!I79*9/5+32 -> 55.094 | J79: ='2020'!J79*9/5+32 -> 53.474 | ... AF79: ='2020'!AF79*9/5+32 -> 55.634

Sheet Averaged All Years
C1: NBP | F1: NBP - 38 | I1: PB1 | L1: PB1-38 | O1: PB2 | R1: PB2-38 | U1: PB3 | X1: PB4 | AA1: PB5 | AD1: PB6
A2: Date | B2: JDAY | C2: AveFol | D2: AveWatt | E2: AveHazel | F2: AveFol | G2: AveWatt | H2: AveHazel | I2: AveFol | J2: AveWatt | K2: AveHazel | L2: AveFol | M2: AveWatt | N2: AveHazel | O2: AveFol | P2: AveWatt | Q2: AveHazel | R2: AveFol | S2: AveWatt | T2: AveHazel | U2: AveFol | V2: AveWatt | W2: AveHazel | X2: AveFol | Y2: AveWatt | Z2: AveHazel | AA2: AveFol | AB2: AveWatt | AC2: AveHazel | AD2: AveFol | AE2: AveWatt | AF2: AveHazel
A3: 46280 | B3: 258 | C3: =AVERAGE('2011'!C3,'2014'!C3,'2017'!C3,'2020'!C3) -> 18.145 | E3: =AVERAGE('2011'!E3,'2014'!E3,'2017'!E3,'2020'!E3) -> 18.4675 | F3: =AVERAGE('2011'!F3,'2014'!F3,'2017'!F3,'2020'!F3) -> 18.145 | H3: =AVERAGE('2011'!H3,'2014'!H3,'2017'!H3,'2020'!H3) -> 18.4675 | I3: =AVERAGE('2011'!I3,'2014'!I3,'2017'!I3,'2020'!I3) -> 18.145 | K3: =AVERAGE('2011'!K3,'2014'!K3,'2017'!K3,'2020'!K3) -> 18.4675 | L3: =AVERAGE('2011'!L3,'2014'!L3,'2017'!L3,'2020'!L3) -> 18.145 | N3: =AVERAGE('2011'!N3,'2014'!N3,'2017'!N3,'2020'!N3) -> 18.4675 | O3: =AVERAGE('2011'!O3,'2014'!O3,'2017'!O3,'2020'!O3) -> 18.145 | Q3: =AVERAGE('2011'!Q3,'2014'!Q3,'2017'!Q3,'2020'!Q3) -> 18.4675 | R3: =AVERAGE('2011'!R3,'2014'!R3,'2017'!R3,'2020'!R3) -> 18.145 | T3: =AVERAGE('2011'!T3,'2014'!T3,'2017'!T3,'2020'!T3) -> 18.4675 | U3: =AVERAGE('2011'!U3,'2014'!U3,'2017'!U3,'2020'!U3) -> 18.145 | W3: =AVERAGE('2011'!W3,'2014'!W3,'2017'!W3,'2020'!W3) -> 18.4675 | X3: =AVERAGE('2011'!X3,'2014'!X3,'2017'!X3,'2020'!X3) -> 18.145 | Z3: =AVERAGE('2011'!Z3,'2014'!Z3,'2017'!Z3,'2020'!Z3) -> 18.4675 | AA3: =AVERAGE('2011'!AA3,'2014'!AA3,'2017'!AA3,'2020'!AA3) -> 18.145 | AC3: =AVERAGE('2011'!AC3,'2014'!AC3,'2017'!AC3,'2020'!AC3) -> 18.4675 | AD3: =AVERAGE('2011'!AD3,'2014'!AD3,'2017'!AD3,'2020'!AD3) -> 18.145 | AF3: =AVERAGE('2011'!AF3,'2014'!AF3,'2017'!AF3,'2020'!AF3) -> 18.4675
A4: 46281 | B4: 259 | C4: =AVERAGE('2011'!C4,'2014'!C4,'2017'!C4,'2020'!C4) -> 19.635 | E4: =AVERAGE('2011'!E4,'2014'!E4,'2017'!E4,'2020'!E4) -> 19.46 | F4: =AVERAGE('2011'!F4,'2014'!F4,'2017'!F4,'2020'!F4) -> 19.635 | H4: =AVERAGE('2011'!H4,'2014'!H4,'2017'!H4,'2020'!H4) -> 19.46 | I4: =AVERAGE('2011'!I4,'2014'!I4,'2017'!I4,'2020'!I4) -> 19.635 | K4: =AVERAGE('2011'!K4,'2014'!K4,'2017'!K4,'2020'!K4) -> 19.46 | L4: =AVERAGE('2011'!L4,'2014'!L4,'2017'!L4,'2020'!L4) -> 19.635 | N4: =AVERAGE('2011'!N4,'2014'!N4,'2017'!N4,'2020'!N4) -> 19.46 | O4: =AVERAGE('2011'!O4,'2014'!O4,'2017'!O4,'2020'!O4) -> 19.635 | Q4: =AVERAGE('2011'!Q4,'2014'!Q4,'2017'!Q4,'2020'!Q4) -> 19.46 | R4: =AVERAGE('2011'!R4,'2014'!R4,'2017'!R4,'2020'!R4) -> 19.635 | T4: =AVERAGE('2011'!T4,'2014'!T4,'2017'!T4,'2020'!T4) -> 19.46 | U4: =AVERAGE('2011'!U4,'2014'!U4,'2017'!U4,'2020'!U4) -> 19.635 | W4: =AVERAGE('2011'!W4,'2014'!W4,'2017'!W4,'2020'!W4) -> 19.46 | X4: =AVERAGE('2011'!X4,'2014'!X4,'2017'!X4,'2020'!X4) -> 19.635 | Z4: =AVERAGE('2011'!Z4,'2014'!Z4,'2017'!Z4,'2020'!Z4) -> 19.46 | AA4: =AVERAGE('2011'!AA4,'2014'!AA4,'2017'!AA4,'2020'!AA4) -> 19.635 | AC4: =AVERAGE('2011'!AC4,'2014'!AC4,'2017'!AC4,'2020'!AC4) -> 19.46 | AD4: =AVERAGE('2011'!AD4,'2014'!AD4,'2017'!AD4,'2020'!AD4) -> 19.635 | AF4: =AVERAGE('2011'!AF4,'2014'!AF4,'2017'!AF4,'2020'!AF4) -> 19.46
A5: 46282 | B5: 260 | C5: =AVERAGE('2011'!C5,'2014'!C5,'2017'!C5,'2020'!C5) -> 18.8625 | E5: =AVERAGE('2011'!E5,'2014'!E5,'2017'!E5,'2020'!E5) -> 18.93 | F5: =AVERAGE('2011'!F5,'2014'!F5,'2017'!F5,'2020'!F5) -> 18.8625 | H5: =AVERAGE('2011'!H5,'2014'!H5,'2017'!H5,'2020'!H5) -> 18.93 | I5: =AVERAGE('2011'!I5,'2014'!I5,'2017'!I5,'2020'!I5) -> 18.8625 | K5: =AVERAGE('2011'!K5,'2014'!K5,'2017'!K5,'2020'!K5) -> 18.93 | L5: =AVERAGE('2011'!L5,'2014'!L5,'2017'!L5,'2020'!L5) -> 18.8625 | N5: =AVERAGE('2011'!N5,'2014'!N5,'2017'!N5,'2020'!N5) -> 18.93 | O5: =AVERAGE('2011'!O5,'2014'!O5,'2017'!O5,'2020'!O5) -> 18.8625 | Q5: =AVERAGE('2011'!Q5,'2014'!Q5,'2017'!Q5,'2020'!Q5) -> 18.93 | R5: =AVERAGE('2011'!R5,'2014'!R5,'2017'!R5,'2020'!R5) -> 18.8625 | T5: =AVERAGE('2011'!T5,'2014'!T5,'2017'!T5,'2020'!T5) -> 18.93 | U5: =AVERAGE('2011'!U5,'2014'!U5,'2017'!U5,'2020'!U5) -> 18.8625 | W5: =AVERAGE('2011'!W5,'2014'!W5,'2017'!W5,'2020'!W5) -> 18.93 | X5: =AVERAGE('2011'!X5,'2014'!X5,'2017'!X5,'2020'!X5) -> 18.8625 | Z5: =AVERAGE('2011'!Z5,'2014'!Z5,'2017'!Z5,'2020'!Z5) -> 18.93 | AA5: =AVERAGE('2011'!AA5,'2014'!AA5,'2017'!AA5,'2020'!AA5) -> 18.8625 | AC5: =AVERAGE('2011'!AC5,'2014'!AC5,'2017'!AC5,'2020'!AC5) -> 18.93 | AD5: =AVERAGE('2011'!AD5,'2014'!AD5,'2017'!AD5,'2020'!AD5) -> 18.8625 | AF5: =AVERAGE('2011'!AF5,'2014'!AF5,'2017'!AF5,'2020'!AF5) -> 18.93
